Workbook

Sheet Respuestas de formulario 1
A1: Marca temporal | B1: Dirección de correo electrónico | C1: Nombre OFICIAL y COMPLETO de la institución educativa | D1: codigo unico de escuela (cue) | E1: tipo de institucion educativa y orientacion | F1: Especifique su orientación | G1: tipo de gestion de la institucion educativa | H1: apellido y nombre del/la docente responsable de la visita | I1: Nombre y apellido del/la docente acompañante 1 | J1: Nombre y apellido del/la docente acompañante 2 | K1: Dirección de correo electrónico para recibir resultado de la asignación | L1: ubicacion de la escuela | M1: Barrio/Localidad de la escuela | N1: cantidad de alumnos que asistiran | O1: curso que asistira | P1: Conectividad en la institución | Q1: Acceso a las ciencias exactas y naturales | R1: porcentaje aproximado de estudiantes de familias de bajos recursos | S1: Exprese observaciones o comentarios que considere pertinentes | T1: Turno/s solicitado/s [Turno mañana (9:00 a 12.30 hs.)] | U1: Turno/s solicitado/s [Turno tarde (12.30 a 16:00 hs.)] | V1: turno solicitado | W1: fecha solicitada | X1: CHARLAS [9:30 Redes sociales: la matemática detrás de los "influencers". Rocío Balderrama] | Y1: CHARLAS [11:30 La Biblio junto a... la calculadora. Historias que no hacen historia. Juan Carlos Pedraza] | Z1: CHARLAS [14:00 ¿Cómo hacer ciencia con Twitter? Sofía del Pozo] | AA1: ESTACIONES INTERACTIVAS [9:30] | AB1: ESTACIONES INTERACTIVAS [10:30] | AC1: ESTACIONES INTERACTIVAS [11:30] | AD1: ESTACIONES INTERACTIVAS [13:00] | AE1: ESTACIONES INTERACTIVAS [14:00] | AF1: ESTACIONES INTERACTIVAS [15:00] | AG1: TALLERES [9:30] | AH1: TALLERES [10:30] | AI1: TALLERES [11:30] | AJ1: TALLERES [14:00] | AK1: TALLERES [15:00] | AL1: ARTE MATEMÁTICO [9:30] | AM1: ARTE MATEMÁTICO [10:30] | AN1: ARTE MATEMÁTICO [11:30] | AO1: ARTE MATEMÁTICO [14:00] | AP1: ARTE MATEMÁTICO [15:00] | AQ1: VISITAS GUIADAS TEMÁTICAS [10:30] | AR1: VISITAS GUIADAS TEMÁTICAS [11:30] | AS1: VISITAS GUIADAS TEMÁTICAS [14:00] | AT1: VISITAS GUIADAS TEMÁTICAS [15:00] | AU1: Exprese cualquier aclaración sobre la solicitud de inscripción que facilite la administración de vacantes. | AV1: CHARLAS [9:30 Desorden ordenado, ¡qué caos es esto! Paula Kuna] | AW1: CHARLAS [11:30 ¿Tenés una idea para cambiar el mundo? Primero simulalo. Rodrigo Castro] | AX1: CHARLAS [14:00 Embaldosados Fractales. Ursula Molter] | AY1: ESTACIONES INTERACTIVAS [9:30] | AZ1: ESTACIONES INTERACTIVAS [10:30] | BA1: ESTACIONES INTERACTIVAS [11:30] | BB1: ESTACIONES INTERACTIVAS [13:00] | BC1: ESTACIONES INTERACTIVAS [14:00] | BD1: ESTACIONES INTERACTIVAS [15:00] | BE1: TALLERES [9.30] | BF1: TALLERES [10:30] | BG1: TALLERES [11:30] | BH1: TALLERES [14:00] | BI1: TALLERES [15:00] | BJ1: ARTE MATEMÁTICO [9:30] | BK1: ARTE MATEMÁTICO [10:30] | BL1: ARTE MATEMÁTICO [11:30] | BM1: ARTE MATEMÁTICO [14:00] | BN1: ARTE MATEMÁTICO [15:00] | BO1: VISITA GUIADA [10:30] | BP1: VISITA GUIADA [11:30] | BQ1: VISITA GUIADA [14:00] | BR1: VISITA GUIADA [15:00] | BS1: Exprese cualquier aclaración sobre la solicitud de inscripción que facilite la administración de vacantes. | BT1: CHARLAS [9:30 Geometría proyectiva, fotografía y la final del mundo. Charly Di Fiore] | BU1: CHARLAS [11:30 Detective de datos. Guillermo Solovey] | BV1: CHARLAS [14:00 Datos y deportes. Iván Monardo] | BW1: ESTACIONES INTERACTIVAS [9:30] | BX1: ESTACIONES INTERACTIVAS [10:30] | BY1: ESTACIONES INTERACTIVAS [11:30] | BZ1: ESTACIONES INTERACTIVAS [13:00] | CA1: ESTACIONES INTERACTIVAS [14:00] | CB1: ESTACIONES INTERACTIVAS [15:00] | CC1: TALLERES [9:30] | CD1: TALLERES [10:30 ] | CE1: TALLERES [11:30] | CF1: TALLERES [14:00] | CG1: TALLERES [15:00] | CH1: ARTE MATEMÁTICO [9:30] | CI1: ARTE MATEMÁTICO [10:30] | CJ1: ARTE MATEMÁTICO [11:30] | CK1: ARTE MATEMÁTICO [14:00] | CL1: ARTE MATEMÁTICO [15:00] | CM1: VISITA GUIADA [10:30] | CN1: VISITA GUIADA [11:30] | CO1: VISITA GUIADA [14:00] | CP1: VISITA GUIADA [15:00] | CQ1: Exprese cualquier aclaración sobre la solicitud de inscripción que facilite la administración de vacantes.
A2: 45363.484 | B2: alvarezmarisaclaudia@gmail.com | C2: Instituto Saenz | D2: 051 | E2: 1. Liceos / Normales / Colegios / Institutos orientados en ciencias naturales y/o exactas | F2: Ciencias naturales | G2: Privada | H2: Marisa Álvarez | I2: Carla Sureda | J2: Andrea Ledesma | K2: alvarezmarisaclaudia@gmail.com | L2: PARTIDOS DEL GRAN BUENOS AIRES-SUR | M2: Lomas de zamorac | N2: 35 | O2: 6º Secundaria (Prov.) / 5º Media (CABA) | P2: 1 | Q2: 4 | R2: 50 | T2: Si | U2: No | V2: Jornada simple: sólo turno mañana (9:00 a 12.30 hs.) | W2: Miércoles 24/4 | AR2: Si | AS2: Si | AT2: Si | AU2: No | AV2: Si | AW2: Si | AX2: Si | AY2: No | AZ2: No | BA2: No | BB2: Si | BC2: Si | BD2: Si | BE2: No | BF2: No | BG2: Si | BH2: Si | BI2: No | BJ2: No
A3: 45363.487 | B3: muestra034@gmail.com | C3: Instituto Sáenz | D3: 051 | E3: 1. Liceos / Normales / Colegios / Institutos orientados en ciencias naturales y/o exactas | F3: C naturales | G3: Privada | H3: Mauro Uranga | I3: Marisa Álvarez | J3: Carla sureda | K3: muestra034@gmail.com | L3: PARTIDOS DEL GRAN BUENOS AIRES-SUR | M3: Lomas de samorac | N3: 35 | O3: 6º Secundaria (Prov.) / 5º Media (CABA) | P3: 2 | Q3: 3 | R3: 50 | T3: Si | U3: No | V3: Jornada simple: sólo turno mañana (9:00 a 12.30 hs.) | W3: Miércoles 24/4 | AR3: Si | AS3: Si | AT3: Si | AU3: No | AV3: Si | AW3: Si | AX3: Si | AY3: No | AZ3: No | BA3: No | BB3: Si | BC3: Si | BD3: Si | BE3: No | BF3: No | BG3: Si | BH3: Si | BI3: No | BJ3: No
A4: 45363.49 | B4: jmarinelli@dellibertador.edu.ar | C4: INST. COLEGIO DEL LIBERTADOR | D4: 020125200 | E4: 9. Liceos / Normales / Colegios / Institutos orientados en ciencias sociales y/o humanidades | F4: Orientación en Lenguas Extranjeras y en Ciencias Sociales y Humanidades | G4: Privada | H4: Javier Marinelli | I4: Damian Vattimo | J4: Marina Lavigna | K4: jmarinelli@dellibertador.edu.ar | L4: CABA | M4: FLORES | N4: 26 | O4: 6º Secundaria (Prov.) / 5º Media (CABA) | P4: 4 | Q4: 3 | R4: 0 | S4: NINGUNO | T4: Si | U4: No | V4: Jornada simple: sólo turno mañana (9:00 a 12.30 hs.) | W4: Miércoles 24/4 | AR4: Si | AS4: No | AT4: No | AU4: No | AV4: No | AW4: Si | AX4: No | AY4: No | AZ4: No | BA4: No | BB4: No | BC4: No | BD4: Si | BE4: No | BF4: No | BG4: No | BH4: No | BI4: No | BJ4: No
A5: 45363.492 | B5: jmarinelli@dellibertador.edu.ar | C5: INST. COLEGIO DEL LIBERTADOR | D5: 020125200 | E5: 9. Liceos / Normales / Colegios / Institutos orientados en ciencias sociales y/o humanidades | F5: Orientación en Lenguas Extranjeras y Ciencias Sociales y Humanidades | G5: Privada | H5: Javier Marinelli | I5: Damian Vattimo | J5: Marina Lavigna | K5: jmarinelli@dellibertador.edu.ar | L5: CABA | M5: FLORES | N5: 19 | O5: 6º Secundaria (Prov.) / 5º Media (CABA) | P5: 4 | Q5: 3 | R5: 0 | S5: NINGUNA | T5: Si | U5: No | V5: Jornada simple: sólo turno mañana (9:00 a 12.30 hs.) | W5: Miércoles 24/4 | AR5: Si | AS5: No | AT5: No | AU5: No | AV5: No | AW5: Si | AX5: No | AY5: No | AZ5: No | BA5: No | BB5: No | BC5: No | BD5: Si | BE5: No | BF5: No | BG5: No | BH5: No | BI5: No | BJ5: No
A6: 45363.493 | B6: m.alvarez@institutosaenz.edu.ar | C6: Instituto saenz | D6: 051 | E6: 1. Liceos / Normales / Colegios / Institutos orientados en ciencias naturales y/o exactas | F6: Cnaturalez | G6: Privada | H6: Laura Condo | I6: Gabriel Celuberti | J6: Belen Bruno | K6: m.alvarez@institutosaenz.edu.ar | L6: PARTIDOS DEL GRAN BUENOS AIRES-SUR | M6: Lomas de Zamora | N6: 35 | O6: 6º Secundaria (Prov.) / 5º Media (CABA) | P6: 2 | Q6: 3 | R6: 50 | T6: Si | U6: No | V6: Jornada simple: sólo turno mañana (9:00 a 12.30 hs.) | W6: Miércoles 24/4 | AR6: Si | AS6: Si | AT6: Si | AU6: No | AV6: Si | AW6: Si | AX6: Si | AY6: No | AZ6: No | BA6: No | BB6: Si | BC6: Si | BD6: Si | BE6: No | BF6: No | BG6: Si | BH6: Si | BI6: No | BJ6: No
A7: 45363.503 | B7: mcappussi@yahoo.com.ar | C7: EES N 2 Francisco Ramírez Lanus | D7: 061024600 | E7: 1. Liceos / Normales / Colegios / Institutos orientados en ciencias naturales y/o exactas | F7: Naturales | G7: Estatal | H7: Cappussi Mercedes | I7: Maria Jose Ferrer | K7: mcappussi@yahoo.com.ar | L7: PARTIDOS DEL GRAN BUENOS AIRES-SUR | M7: Lanus | N7: 25 | O7: 6º Secundaria (Prov.) / 5º Media (CABA) | P7: 5 | Q7: 5 | R7: 50 | T7: Si | U7: Si | V7: Jornada completa: turno completo (9:00 a 16.00 hs.) | W7: Miércoles 24/4 | AR7: No | AS7: Si | AT7: Si | AU7: No | AV7: Si | AW7: No | AX7: No | AY7: No | AZ7: Si | BA7: Si | BB7: No | BC7: Si | BD7: Si | BE7: Si | BF7: No | BG7: No | BH7: No | BI7: Si | BJ7: No
A8: 45363.506 | B8: mcappussi@yahoo.com.ar | C8: EES N 2 Francisco Ramírez | D8: 061024600 | E8: 1. Liceos / Normales / Colegios / Institutos orientados en ciencias naturales y/o exactas | F8: Economía | G8: Estatal | H8: Cappussi Mercedes | I8: Ferrer María jose | K8: mcappussi@yahoo.com.ar | L8: PARTIDOS DEL GRAN BUENOS AIRES-SUR | M8: Lanus | N8: 20 | O8: 6º Secundaria (Prov.) / 5º Media (CABA) | P8: 5 | Q8: 5 | R8: 50 | T8: Si | U8: Si | V8: Jornada completa: turno completo (9:00 a 16.00 hs.) | W8: Miércoles 24/4 | AR8: No | AS8: Si | AT8: Si | AU8: No | AV8: Si | AW8: No | AX8: No | AY8: No | AZ8: Si | BA8: No | BB8: No | BC8: Si | BD8: Si | BE8: Si | BF8: No | BG8: No | BH8: No | BI8: Si | BJ8: No
A9: 45363.517 | B9: morelli.nicolas.a@gmail.com | C9: Colegio Norbridge | D9: 020082300 | E9: 1. Liceos / Normales / Colegios / Institutos orientados en ciencias naturales y/o exactas | F9: Administración | G9: Privada | H9: Nicolás Morelli | I9: Analia Mezzelani | J9: Liliana Villena | K9: morelli.nicolas.a@gmail.com | L9: CABA | M9: Saavedra | N9: 30 | O9: 6º Secundaria (Prov.) / 5º Media (CABA) | P9: 5 | Q9: 5 | R9: 5 | S9: En lo posible nos gustaría recibir la visita guiada para que los estudiantes conozcan las instalaciones. Gracias! | T9: Si | U9: No | V9: Jornada simple: sólo turno mañana (9:00 a 12.30 hs.) | W9: Miércoles 24/4 | AR9: Si | AS9: No | AT9: No | AU9: No | AV9: No | AW9: No | AX9: Si | AY9: No | AZ9: No | BA9: No | BB9: No | BC9: No | BD9: Si | BE9: No | BF9: No | BG9: Si | BH9: No | BI9: No | BJ9: No | BK9: Por favor en lo posible nos gustaría acceder a la visita guiada. Muchas gracias por todo el trabajo!
A10: 45363.525 | B10: ctoperberg@colegio-isma.com.ar | C10: Instituto Santa María de los Ángeles (A-455) | D10: 020038700 | E10: 1. Liceos / Normales / Colegios / Institutos orientados en ciencias naturales y/o exactas | F10: Bachillerato en Ciencias Naturales | G10: Privada | H10: Lucas Caram | I10: Camila Toperberg | K10: ctoperberg@colegio-isma.com.ar | L10: CABA | M10: Coghlan | N10: 30 | O10: 6º Secundaria (Prov.) / 5º Media (CABA) | P10: 4 | Q10: 3 | R10: 5 | T10: Si | U10: No | V10: Jornada simple: sólo turno mañana (9:00 a 12.30 hs.) | W10: Miércoles 24/4 | AR10: Si | AS10: No | AT10: No | AU10: No | AV10: No | AW10: No | AX10: Si | AY10: No | AZ10: No | BA10: No | BB10: No | BC10: Si | BD10: No | BE10: No | BF10: No | BG10: No | BH10: No | BI10: No | BJ10: No
A11: 45363.536 | B11: agustinpereyra@abc.gob.ar | C11: Colegio Madre Teresa | D11: 061690800 | E11: 10. Liceos / Normales / Colegios / Institutos de otras orientaciones | F11: Economía | G11: Privada | H11: Pereyra Varela Agustín | I11: Simón Sabrina | J11: Baini Jesica | K11: agustinpereyra@abc.gob.ar | L11: PARTIDOS DEL GRAN BUENOS AIRES-NORTE | M11: Virreyes | N11: 25 | O11: 6º Secundaria (Prov.) / 5º Media (CABA) | P11: 2 | Q11: 2 | R11: 80 | T11: Si | U11: Si | V11: Jornada completa: turno completo (9:00 a 16.00 hs.) | W11: Miércoles 24/4 | AR11: Si | AS11: No | AT11: No | AU11: No | AV11: No | AW11: Si | AX11: No | AY11: No | AZ11: Si | BA11: No | BD11: Si | BJ11: Si
A12: 45363.54 | B12: agustinpereyra@abc.gob.ar | C12: Colegio Madre Teresa | D12: 061690800 | E12: 10. Liceos / Normales / Colegios / Institutos de otras orientaciones | F12: Economía | G12: Privada | H12: Pereyra Varela Agustín | I12: Simón Sabrina | J12: Nuñez Silvina | K12: agustinpereyra@abc.gob.ar | L12: PARTIDOS DEL GRAN BUENOS AIRES-NORTE | M12: Virreyes | N12: 25 | O12: 6º Secundaria (Prov.) / 5º Media (CABA) | P12: 2 | Q12: 2 | R12: 80 | T12: Si | U12: Si | V12: Jornada completa: turno completo (9:00 a 16.00 hs.) | W12: Miércoles 24/4 | AR12: Si | AS12: No | AT12: No | AU12: No | AV12: No | AW12: Si | AX12: No | AY12: No | AZ12: Si | BA12: No | BD12: Si | BJ12: Si
A13: 45363.608 | B13: veronica.garces@bue.edu.ar | C13: Colegio N 17 DE 7 | D13: 20135200 | E13: 9. Liceos / Normales / Colegios / Institutos orientados en ciencias sociales y/o humanidades | F13: Bachiller orientación en ciencias sociales | G13: Estatal | H13: Verónica Garcés | I13: Mancuso Laura | J13: Claudia Uzal | K13: veronica.garces@bue.edu.ar | L13: CABA | M13: Caballito3 | N13: 35 | O13: 5º Secundaria (Prov.) / 4º Media (CABA) | P13: 5 | Q13: 5 | R13: 60 | T13: Si | U13: No | V13: Jornada simple: sólo turno mañana (9:00 a 12.30 hs.) | W13: Miércoles 24/4 | AR13: Si | AS13: Si | AT13: Si | AU13: Si | AV13: Si | AW13: Si | AX13: Si | AY13: Si | AZ13: Si | BA13: Si | BB13: Si | BC13: Si | BD13: Si | BE13: Si | BF13: Si | BG13: Si | BH13: Si | BI13: Si | BJ13: Si
A14: 45363.627 | B14: patferre@gmail.com | C14: Instituto San Luis | D14: 060407300 | E14: 1. Liceos / Normales / Colegios / Institutos orientados en ciencias naturales y/o exactas | F14: Cs Naturales | G14: Privada | H14: Patricia Ferreyra | I14: Alicia Gil | J14: Nicolas Ambrosoni | K14: patferre@gmail.com | L14: PARTIDOS DEL GRAN BUENOS AIRES-NORTE | M14: Victoria/ San Fernando | N14: 35 | O14: 6º Secundaria (Prov.) / 5º Media (CABA) | P14: 4 | Q14: 4 | R14: 20 | S14: Es colegio subvencionado | T14: Si | U14: No | V14: Jornada simple: sólo turno mañana (9:00 a 12.30 hs.) | W14: Miércoles 24/4 | AR14: Si | AS14: No | AT14: No | AU14: Si | AV14: No | AW14: Si | AX14: Si | AY14: Si | AZ14: No | BA14: No | BB14: Si | BC14: Si | BD14: Si | BE14: No | BF14: No | BG14: No | BH14: No | BI14: No | BJ14: No | BK14: Puede dividirse en 2 subgrupos. Asistiremos con otro curso del mismo colegio
A15: 45363.631 | B15: patferre@gmail.com | C15: Instituto San Luis | D15: 060407300 | E15: 1. Liceos / Normales / Colegios / Institutos orientados en ciencias naturales y/o exactas | F15: Naturales y sociales | G15: Privada | H15: Alicia Gil | I15: Patricia Ferreyra | J15: Nicolás Ambrosoni | K15: patferre@gmail.com | L15: PARTIDOS DEL GRAN BUENOS AIRES-NORTE | M15: Victoria/San Fernando | N15: 35 | O15: 6º Secundaria (Prov.) / 5º Media (CABA) | P15: 4 | Q15: 4 | R15: 20 | S15: Es subvencionado, los cursos tienen ambas orientaciones | T15: Si | U15: No | V15: Jornada simple: sólo turno mañana (9:00 a 12.30 hs.) | W15: Miércoles 24/4 | AR15: Si | AS15: No | AT15: No | AU15: Si | AV15: No | AW15: Si | AX15: Si | AY15: Si | AZ15: No | BA15: No | BB15: Si | BC15: Si | BD15: Si | BE15: No | BF15: No | BG15: No | BH15: No | BI15: No | BJ15: No | BK15: Pueden dividirse en 2 subgrupos. Agradeceremos asistir los 2 cursos del colegio.
A16: 45363.661 | B16: horaciovarela@institutosanfelipeneri.edu.ar | C16: Instituto San Felipe Neri | D16: 020130000 | E16: 7. Técnicas en diseño (gráfico, interiores, comunicación publicitaria, artesanías, indumentaria, mueble, orfebrería, jardinería y paisajismo) | F16: Informatico | G16: Privada | H16: Horacio Varela | I16: Pablo Gonzalez | J16: Laura Vaamonde | K16: horaciovarela@institutosanfelipeneri.edu.ar | L16: CABA | M16: Mataderos | N16: 35 | O16: 6º Secundaria (Prov.) / 5º Media (CABA) | P16: 4 | Q16: 4 | R16: 30 | T16: Si | U16: No | V16: Jornada simple: sólo turno mañana (9:00 a 12.30 hs.) | W16: Miércoles 24/4 | AR16: Si | AS16: Si | AT16: Si | AU16: Si | AV16: Si | AW16: Si | AX16: Si | AY16: Si | AZ16: Si | BA16: Si | BB16: Si | BC16: Si | BD16: Si | BE16: Si | BF16: Si | BG16: Si | BH16: Si | BI16: Si | BJ16: Si
A17: 45363.691 | B17: gabriela.gonzalog@gmail.com | C17: Colegio Irlandes | D17: 061602200 | E17: 9. Liceos / Normales / Colegios / Institutos orientados en ciencias sociales y/o humanidades | F17: Ciencias sociales | G17: Privada | H17: Gabriela Gonzalo Grilo | I17: Sabrina Alvarenga | J17: Romina Ramos | K17: gabriela.gonzalog@gmail.com | L17: PARTIDOS DEL GRAN BUENOS AIRES-SUR | M17: Almirante Brown | N17: 23 | O17: 6º Secundaria (Prov.) / 5º Media (CABA) | P17: 4 | Q17: 3 | R17: 0 | T17: Si | U17: No | V17: Jornada simple: sólo turno mañana (9:00 a 12.30 hs.) | W17: Miércoles 24/4 | AR17: Si | AS17: Si | AT17: Si | AU17: No | AV17: Si | AW17: Si | AX17: Si | AY17: No | AZ17: No | BA17: No | BB17: Si | BC17: Si | BD17: Si | BE17: No | BF17: No | BG17: Si | BH17: Si | BI17: No | BJ17: No | BK17: Es una hermosa oportunidad de hacer matemática y de que conozcan la facultad. Muchas gracias
A18: 45363.718 | B18: lucilazobra@beataimelda.org | C18: INSTITUTO BEATA IMELDA | D18: 020067400 | E18: 9. Liceos / Normales / Colegios / Institutos orientados en ciencias sociales y/o humanidades | F18: Sociales y Humanidades | G18: Privada | H18: Lucila Zobra | I18: Rodrigo Riedel | J18: Andrea Chiola | K18: lucilazobra@beataimelda.org | L18: CABA | M18: Villa Urquiza | N18: 30 | O18: 6º Secundaria (Prov.) / 5º Media (CABA) | P18: 3 | Q18: 3 | R18: 50 | T18: Si | U18: No | V18: Jornada simple: sólo turno mañana (9:00 a 12.30 hs.) | W18: Miércoles 24/4 | AR18: Si | AS18: Si | AT18: Si | AU18: No | AV18: Si | AW18: Si | AX18: Si | AY18: No | AZ18: No | BA18: No | BB18: Si | BC18: Si | BD18: Si | BE18: No | BF18: No | BG18: Si | BH18: Si | BI18: No | BJ18: No | BK18: No tengo problema con la asignación de horarios dentro del turno y, si bien elegí el miércoles 25/4 también podría concurrir el jueves 26.
A19: 45363.721 | B19: lucilazobra@beataimelda.org | C19: INSTITUTO BEATA IMELDA | D19: 020067400 | E19: 10. Liceos / Normales / Colegios / Institutos de otras orientaciones | F19: Economía y Administración | G19: Privada | H19: Lucila Zobra | I19: María Arangue | J19: María Eugenia Castro | K19: lucilazobra@beataimelda.org | L19: CABA | M19: Villa Urquiza | N19: 34 | O19: 6º Secundaria (Prov.) / 5º Media (CABA) | P19: 3 | Q19: 3 | R19: 50 | S19: No tengo problema con la asignación de horarios dentro del turno y, si bien elegí el miércoles 25/4 también podría concurrir el jueves 26. | T19: Si | U19: No | V19: Jornada simple: sólo turno mañana (9:00 a 12.30 hs.) | W19: Miércoles 24/4 | AR19: Si | AS19: Si | AT19: Si | AU19: No | AV19: Si | AW19: Si | AX19: Si | AY19: No | AZ19: No | BA19: No | BB19: Si | BC19: Si | BD19: Si | BE19: No | BF19: No | BG19: Si | BH19: Si | BI19: No | BJ19: No | BK19: No tengo problema con la asignación de horarios dentro del turno y, si bien elegí el miércoles 25/4 también podría concurrir el jueves 26.
A20: 45363.732 | B20: zelayaandrea@hotmail.com | C20: El Bosque | D20: 6020645.00 | E20: 1. Liceos / Normales / Colegios / Institutos orientados en ciencias naturales y/o exactas | F20: Exactas | G20: Privada | H20: Gliozzi Sandra noemi | I20: . | J20: . | K20: zelayaandrea@hotmail.com | L20: PARTIDOS DEL GRAN BUENOS AIRES-SUR | M20: Almirante Brown | N20: 30 | O20: 6º Secundaria (Prov.) / 5º Media (CABA) | P20: 5 | Q20: 5 | R20: 0 | S20: . | T20: Si | U20: Si | V20: Jornada completa: turno completo (9:00 a 16.00 hs.) | W20: Miércoles 24/4 | AR20: Si | AS20: No | AT20: No | AU20: No | AV20: No | AW20: Si | AX20: No | AY20: No | AZ20: No | BA20: No | BB20: No | BC20: Si | BD20: No | BE20: No | BF20: No | BG20: No | BH20: Si | BI20: No | BJ20: No
A21: 45363.765 | B21: mapaulasuarez@yahoo.com.ar | C21: Instituto Social Militar Dr Dámaso Centeno | D21: 29003000 | E21: 1. Liceos / Normales / Colegios / Institutos orientados en ciencias naturales y/o exactas | F21: Ciencias Naturales y Gestión | G21: Privada | H21: María Paula Suárez | I21: Lisette Mendez | J21: Bruno Bagniole | K21: mapaulasuarez@yahoo.com.ar | L21: CABA | M21: Caballito | N21: 32 | O21: 6º Secundaria (Prov.) / 5º Media (CABA) | P21: 5 | Q21: 5 | R21: 10 | T21: Si | U21: No | V21: Jornada simple: sólo turno mañana (9:00 a 12.30 hs.) | W21: Miércoles 24/4 | AR21: Si | AS21: Si | AT21: Si | AU21: No | AV21: Si | AW21: Si | AX21: Si | AY21: No | AZ21: No | BA21: No | BB21: Si | BC21: Si | BD21: Si | BE21: No | BF21: No | BG21: Si | BH21: Si | BI21: No | BJ21: No
A22: 45363.789 | B22: julieta.pianetti@bue.edu.ar | C22: ESC. TEC. Nº 30 NORBERTO PINERO DE 02 | D22: 020144800 | E22: 6. Técnicas en química y tecnología de alimentos | F22: Quimica | G22: Estatal | H22: Julieta Pianetti | I22: Alejandra Ciarlantini | J22: Lautaro Aquino | K22: julieta.pianetti@bue.edu.ar | L22: CABA | M22: Almagro | N22: 25 | O22: 5º Secundaria (Prov.) / 4º Media (CABA) | P22: 5 | Q22: 5 | R22: 80 | T22: Si | U22: No | V22: Jornada simple: sólo turno mañana (9:00 a 12.30 hs.) | W22: Miércoles 24/4 | AR22: No | AS22: No | AT22: No | AU22: No | AV22: Si | AW22: No | AX22: No | AY22: No | AZ22: No | BA22: No | BB22: No | BC22: Si | BD22: No | BE22: No | BF22: No | BG22: No | BH22: Si | BI22: No | BJ22: No
A23: 45364.033 | B23: lbusso@colegioeltaller.com.ar | C23: Instituto secundario el taller | D23: 200958 | E23: 10. Liceos / Normales / Colegios / Institutos de otras orientaciones | F23: Comunicación | G23: Privada | H23: María Laura Busso | I23: Rosana Novegil | J23: Carolina Puente | K23: lbusso@colegioeltaller.com.ar | L23: CABA | M23: Boedo | N23: 35 | O23: 6º Secundaria (Prov.) / 5º Media (CABA) | P23: 4 | Q23: 4 | R23: 5 | T23: Si | U23: No | V23: Jornada simple: sólo turno mañana (9:00 a 12.30 hs.) | W23: Miércoles 24/4 | AR23: Si | AS23: Si | AT23: No | AU23: Si | AV23: No | AW23: No | AX23: No | AY23: No | AZ23: No | BA23: No | BB23: Si | BC23: No | BD23: No | BE23: No | BF23: No | BG23: Si | BH23: No | BI23: Si | BJ23: Si
A24: 45364.352 | B24: brian.monzon@sagrado-boulogne.edu.ar | C24: Colegio Sagrado Corazón de Jesús | D24: 061211300 | E24: 1. Liceos / Normales / Colegios / Institutos orientados en ciencias naturales y/o exactas | F24: Economía y administración | G24: Privada | H24: Brian Leonel Monzon | I24: Aldana Carboni | K24: brian.monzon@sagrado-boulogne.edu.ar | L24: PARTIDOS DEL GRAN BUENOS AIRES-NORTE | M24: Boulogne | N24: 25 | O24: 6º Secundaria (Prov.) / 5º Media (CABA) | P24: 3 | Q24: 3 | R24: 60 | T24: Si | U24: No | V24: Jornada simple: sólo turno mañana (9:00 a 12.30 hs.) | W24: Miércoles 24/4 | AR24: Si | AS24: Si | AT24: No | AU24: No | AV24: Si | AW24: Si | AX24: No | AY24: No | AZ24: No | BA24: No | BB24: Si | BC24: Si | BD24: No | BE24: No | BF24: No | BG24: Si | BH24: No | BI24: No | BJ24: No
A25: 45364.355 | B25: juliangosatti@holmbergschule.edu.ar | C25: instituto educativo Eduardo L. Holmberg | D25: 060399600 | E25: 1. Liceos / Normales / Colegios / Institutos orientados en ciencias naturales y/o exactas | F25: Ciencias Naturales | G25: Privada | H25: Julián Gosatti | I25: Florencia Rivas | K25: juliangosatti@holmbergschule.edu.ar | L25: PARTIDOS DEL GRAN BUENOS AIRES-SUR | M25: quilmes | N25: 35 | O25: 6º Secundaria (Prov.) / 5º Media (CABA) | P25: 5 | Q25: 5 | R25: 0 | T25: Si | U25: No | V25: Jornada simple: sólo turno mañana (9:00 a 12.30 hs.) | W25: Miércoles 24/4 | AR25: Si | AS25: Si | AT25: Si | AU25: No | AV25: Si | AW25: Si | AX25: Si | AY25: No | AZ25: No | BA25: No | BB25: Si | BC25: Si | BD25: Si | BE25: No | BF25: No | BG25: Si | BH25: Si | BI25: No | BJ25: No
A26: 45364.425 | B26: pamel_7787@hotmail.com | C26: Escuela de educación secundaria N*22 Morón | D26: 060615900 | E26: 1. Liceos / Normales / Colegios / Institutos orientados en ciencias naturales y/o exactas | F26: Naturales | G26: Estatal | H26: Cintia Borda | I26: José Luis Escalante | J26: Ricarte Yanina | K26: pamel_7787@hotmail.com | L26: PARTIDOS DEL GRAN BUENOS AIRES-OESTE | M26: Morón | N26: 35 | O26: 6º Secundaria (Prov.) / 5º Media (CABA) | P26: 3 | Q26: 3 | R26: 85 | S26: Los chicos desean conocer la UBA ya que varios están pensando seguir sus estudios una vez finalizada la secundaria. | T26: Si | U26: No | V26: Jornada simple: sólo turno mañana (9:00 a 12.30 hs.) | W26: Miércoles 24/4 | AR26: No | AS26: No | AT26: No | AU26: No | AV26: Si | AW26: No | AX26: No | AY26: No | AZ26: No | BA26: No | BB26: No | BC26: Si | BD26: No | BE26: No | BF26: No | BG26: No | BH26: Si | BI26: No | BJ26: No | BK26: Aquellas actividades relacionadas con la aplicación de la matemática a la vida cotidiana y la realidad de los chicos es lo que más nos atrae de la muestra
A27: 45364.429 | B27: brian.monzon@sagrado-boulogne.edu.ar | C27: Colegio Sagrado Corazón de Jesús | D27: 061211300 | E27: 1. Liceos / Normales / Colegios / Institutos orientados en ciencias naturales y/o exactas | F27: Ciencias Sociales | G27: Privada | H27: Brian Monzon | I27: Marcelo Citracca | K27: brian.monzon@sagrado-boulogne.edu.ar | L27: PARTIDOS DEL GRAN BUENOS AIRES-NORTE | M27: Boulogne | N27: 30 | O27: 6º Secundaria (Prov.) / 5º Media (CABA) | P27: 3 | Q27: 3 | R27: 60 | T27: Si | U27: No | V27: Jornada simple: sólo turno mañana (9:00 a 12.30 hs.) | W27: Miércoles 24/4 | AR27: Si | AS27: Si | AT27: No | AU27: No | AV27: Si | AW27: Si | AX27: No | AY27: No | AZ27: No | BA27: No | BB27: Si | BC27: Si | BD27: No | BE27: No | BF27: No | BG27: Si | BH27: No | BI27: No | BJ27: No
A28: 45364.441 | B28: luis.barrio@bue.edu.ar | C28: ESC. DE COM. Nº 20 DR. JUAN AGUSTIN GARCIA DE 14 | D28: 20015900 | E28: 10. Liceos / Normales / Colegios / Institutos de otras orientaciones | F28: Administración y Economía | G28: Estatal | H28: Luis Octavio Barrio | I28: David Nuñez Duarte | K28: luis.barrio@bue.edu.ar | L28: CABA | M28: La Paternal | N28: 35 | O28: 6º Secundaria (Prov.) / 5º Media (CABA) | P28: 4 | Q28: 3 | R28: 50 | T28: Si | U28: No | V28: Jornada simple: sólo turno mañana (9:00 a 12.30 hs.) | W28: Miércoles 24/4 | AR28: Si | AS28: Si | AT28: No | AU28: No | AV28: No | AW28: Si | AX28: Si | AY28: No | AZ28: No | BA28: No | BB28: No | BC28: Si | BD28: Si | BE28: No | BF28: No | BG28: No | BH28: No | BI28: No | BJ28: No | BK28: Prioridad: 9:30 Charla 10:30 Taller 11:30 Estaciones interactivas
A29: 45364.444 | B29: yanina.ricarte@gmail.com | C29: Escuela de educacion secundaria n°22 moron | D29: 060615900 | E29: 1. Liceos / Normales / Colegios / Institutos orientados en ciencias naturales y/o exactas | F29: sociales | G29: Estatal | H29: Adriana Yanina ricarte | I29: Cintia borda | J29: Jose luis escalante | K29: yanina.ricarte@gmail.com | L29: PARTIDOS DEL GRAN BUENOS AIRES-OESTE | M29: Moron | N29: 25 | O29: 6º Secundaria (Prov.) / 5º Media (CABA) | P29: 3 | Q29: 3 | R29: 85 | T29: Si | U29: No | V29: Jornada simple: sólo turno mañana (9:00 a 12.30 hs.) | W29: Miércoles 24/4 | AR29: No | AS29: No | AT29: No | AU29: No | AV29: Si | AW29: No | AX29: No | AY29: No | AZ29: No | BA29: No | BB29: No | BC29: Si | BD29: No | BE29: No | BF29: No | BG29: No | BH29: Si | BI29: No | BJ29: No
A30: 45364.807 | B30: gladys.cristina.albano@gmail.com | C30: Instituto Nuestra Señora del Milagro | D30: 020167500 | E30: 9. Liceos / Normales / Colegios / Institutos orientados en ciencias sociales y/o humanidades | F30: Humanidades | G30: Privada | H30: Gladys Cristina Albano | I30: Gladys Cristina Albano | J30: Gabriela Lopez | K30: gladys.cristina.albano@gmail.com | L30: CABA | M30: Villa Luro | N30: 24 | O30: 5º Secundaria (Prov.) / 4º Media (CABA) | P30: 4 | Q30: 5 | R30: 0 | T30: Si | U30: No | V30: Jornada simple: sólo turno mañana (9:00 a 12.30 hs.) | W30: Miércoles 24/4 | AR30: Si | AS30: No | AT30: No | AU30: No | AV30: No | AW30: Si | AX30: No | AY30: No | AZ30: No | BA30: No | BB30: No | BC30: No | BD30: Si | BE30: No | BF30: No | BG30: No | BH30: Si | BI30: No | BJ30: No
A31: 45364.951 | B31: marisaleg2020@gmail.com | C31: Escuela de educación superior técnica N°3 "Japón" | D31: 0605618 | E31: 2. Técnicas en computación, electrónica, informática | F31: Electromecánica | G31: Estatal | H31: Marisa Leguizamón | I31: Silvia Villalba | J31: Gladys Giordana | K31: marisaleg2020@gmail.com | L31: PARTIDOS DEL GRAN BUENOS AIRES-OESTE | M31: San Miguel | N31: 32 | O31: 4º Secundaria (Prov:) / 3º Media (CABA) | P31: 2 | Q31: 2 | R31: 15 | S31: Ninguno | T31: Si | U31: Si | V31: Jornada completa: turno completo (9:00 a 16.00 hs.) | W31: Miércoles 24/4 | AR31: Si | AS31: No | AT31: Si | AU31: No | AV31: No | AW31: Si | AX31: No | AY31: Si | AZ31: No | BA31: Si | BB31: Si | BC31: No | BD31: No | BE31: Si | BF31: Si | BG31: Si | BH31: No | BI31: No | BJ31: Si
A32: 45365.339 | B32: mabeneto@gmail.com | C32: Escuela de Educación Secundaria Técnica Juan XXIII | D32: 60929900 | E32: 5. Técnicas área producción (electromecánica, mecánica, metalurgia, electricidad, automotores, refrigeración, construcciones, maestro mayor de obras, aeronáutica, naval, aviónico, óptico, en geografía matemática) | F32: Electromecánica | G32: Estatal | H32: Mabel Neto | I32: Norma Randone | J32: Fernanda Ruta | K32: mabeneto@gmail.com | L32: PARTIDOS DEL GRAN BUENOS AIRES-OESTE | M32: Marcos Paz | N32: 35 | O32: 6º Secundaria (Prov.) / 5º Media (CABA) | P32: 5 | Q32: 3 | R32: 50 | T32: Si | U32: Si | V32: Jornada completa: turno completo (9:00 a 16.00 hs.) | W32: Miércoles 24/4 | AR32: No | AS32: No | AT32: Si | AU32: Si | AV32: No | AW32: No | AX32: Si | AY32: Si | AZ32: Si | BA32: Si | BB32: No | BC32: No | BD32: Si | BE32: Si | BF32: Si | BG32: No | BH32: Si | BI32: Si | BJ32: Si
A33: 45365.364 | B33: 045c.arciello@companiademaria.edu.ar | C33: INSTITUTO COMPAÑIA DE MARIA | D33: 020099900 | E33: 9. Liceos / Normales / Colegios / Institutos orientados en ciencias sociales y/o humanidades | F33: Bachiller en Ciencias Sociales y Humanidades | G33: Privada | H33: Carolina Arciello | I33: Martin Carrano | J33: Anabella Lange | K33: caroarciello@gmail.com | L33: CABA | M33: Colegiales | N33: 35 | O33: 6º Secundaria (Prov.) / 5º Media (CABA) | P33: 5 | Q33: 4 | R33: 20 | T33: Si | U33: No | V33: Jornada simple: sólo turno mañana (9:00 a 12.30 hs.) | W33: Miércoles 24/4 | AR33: Si | AS33: Si | AT33: Si | AU33: No | AV33: Si | AW33: Si | AX33: Si | AY33: No | AZ33: No | BA33: No | BB33: Si | BC33: Si | BD33: Si | BE33: No | BF33: No | BG33: Si | BH33: Si | BI33: No | BJ33: No
A34: 45365.365 | B34: 045c.arciello@companiademaria.edu.ar | C34: INSTITUTO COMPAÑIA DE MARIA | D34: 020099900 | E34: 10. Liceos / Normales / Colegios / Institutos de otras orientaciones | F34: Bachiller en Economía y Administración | G34: Privada | H34: Carolina Arciello | I34: Martín Carrano | J34: Anabella Lange | K34: caroarciello@gmail.com | L34: CABA | M34: Colegiales | N34: 35 | O34: 6º Secundaria (Prov.) / 5º Media (CABA) | P34: 5 | Q34: 4 | R34: 20 | T34: Si | U34: No | V34: Jornada simple: sólo turno mañana (9:00 a 12.30 hs.) | W34: Miércoles 24/4 | AR34: Si | AS34: Si | AT34: Si | AU34: No | AV34: Si | AW34: Si | AX34: Si | AY34: No | AZ34: No | BA34: No | BB34: Si | BC34: Si | BD34: Si | BE34: No | BF34: No | BG34: Si | BH34: Si | BI34: No | BJ34: No
A35: 45365.418 | B35: soledadcabodevila@docentes.sanmaron.edu.ar | C35: Instituto San Marón | D35: 20056200 | E35: 9. Liceos / Normales / Colegios / Institutos orientados en ciencias sociales y/o humanidades | F35: Ciencias Sociales y Humanidades | G35: Privada | H35: Soledad Cabodevila | I35: Cecilia Díaz | K35: soledadcabodevila@docentes.sanmaron.edu.ar | L35: CABA | M35: San Nicolás | N35: 11 | O35: 6º Secundaria (Prov.) / 5º Media (CABA) | P35: 3 | Q35: 4 | R35: 10 | T35: Si | U35: No | V35: Jornada simple: sólo turno mañana (9:00 a 12.30 hs.) | W35: Miércoles 24/4 | AR35: Si | AS35: Si | AT35: Si | AU35: No | AV35: Si | AW35: Si | AX35: Si | AY35: Si | AZ35: No | BA35: No | BB35: Si | BC35: Si | BD35: Si | BE35: No | BF35: No | BG35: No | BH35: No | BI35: No | BJ35: No
A36: 45365.488 | B36: felipe.saenzpaz@escueladelmirador.edu.ar | C36: Escuela del Mirador | D36: 20086200 | E36: 9. Liceos / Normales / Colegios / Institutos orientados en ciencias sociales y/o humanidades | F36: En Ciencias Sociales y Humanidades. Educación bilingüe en inglés | G36: Privada | H36: Felipe Saenz Paz | I36: Veronica Mollinari | K36: felipe.saenzpaz@escueladelmirador.edu.ar | L36: CABA | M36: Villa Devoto | N36: 25 | O36: 5º Secundaria (Prov.) / 4º Media (CABA) | P36: 5 | Q36: 3 | R36: 5 | T36: Si | U36: No | V36: Jornada simple: sólo turno mañana (9:00 a 12.30 hs.) | W36: Miércoles 24/4 | AR36: Si | AS36: No | AT36: No | AU36: No | AV36: No | AW36: Si | AX36: No | AY36: No | AZ36: No | BA36: No
A37: 45365.49 | B37: felipe.saenzpaz@escueladelmirador.edu.ar | C37: Escuela del Mirador | D37: 20086200 | E37: 9. Liceos / Normales / Colegios / Institutos orientados en ciencias sociales y/o humanidades | F37: En Ciencias Sociales y Humanidades. Educación bilingüe en inglés | G37: Privada | H37: Felipe Saenz Paz | I37: Veronica Mollineri | K37: felipe.saenzpaz@escueladelmirador.edu.ar | L37: CABA | M37: Villa Devoto | N37: 24 | O37: 6º Secundaria (Prov.) / 5º Media (CABA) | P37: 5 | Q37: 3 | R37: 5 | T37: Si | U37: No | V37: Jornada simple: sólo turno mañana (9:00 a 12.30 hs.) | W37: Miércoles 24/4 | AR37: Si | AS37: No | AT37: No | AU37: No | AV37: No | AW37: Si | AX37: No | AY37: No | AZ37: No | BA37: No
A38: 45365.493 | B38: felipe.saenzpaz@escueladelmirador.edu.ar | C38: Escuela del Mirador | D38: 20086200 | E38: 9. Liceos / Normales / Colegios / Institutos orientados en ciencias sociales y/o humanidades | F38: En Ciencias Sociales y Humanidades. Educación bilingüe en inglés | G38: Privada | H38: Felipe Saenz Paz | I38: Veronica Mollinari | K38: felipe.saenzpaz@escueladelmirador.edu.ar | L38: CABA | M38: Villa Devoto | N38: 25 | O38: 6º Secundaria (Prov.) / 5º Media (CABA) | P38: 5 | Q38: 3 | R38: 5 | T38: Si | U38: No | V38: Jornada simple: sólo turno mañana (9:00 a 12.30 hs.) | W38: Miércoles 24/4 | AR38: Si | AS38: No | AT38: No | AU38: No | AV38: No | AW38: Si | AX38: No | AY38: No | AZ38: No | BA38: No
A39: 45365.581 | B39: jp.alvarez29@gmail.com | C39: Instituto Parroquial Cristo Obrero | D39: 0605718 | E39: 9. Liceos / Normales / Colegios / Institutos orientados en ciencias sociales y/o humanidades | F39: Sociales | G39: Privada | H39: Juan Pablo Alvarez | I39: Vanina Barbera | K39: jp.alvarez29@gmail.com | L39: PARTIDOS DEL GRAN BUENOS AIRES-OESTE | M39: Haedo, Morón | N39: 35 | O39: 6º Secundaria (Prov.) / 5º Media (CABA) | P39: 3 | Q39: 2 | R39: 75 | T39: Si | U39: No | V39: Jornada simple: sólo turno mañana (9:00 a 12.30 hs.) | W39: Miércoles 24/4 | AR39: Si | AS39: No | AT39: No | AU39: No | AV39: No | AW39: Si | AX39: No | AY39: No | AZ39: No | BA39: No | BB39: No | BC39: No | BD39: No | BE39: Si | BF39: No | BG39: No | BH39: Si | BI39: No | BJ39: No
A40: 45365.595 | B40: eri.bet.80@gmail.com | C40: EES27 de José C. Paz | D40: 061744400 | E40: 1. Liceos / Normales / Colegios / Institutos orientados en ciencias naturales y/o exactas | F40: Cs Naturales | G40: Estatal | H40: Pogonza Erica | I40: Ferrier Leris | J40: Núñez Vanesa | K40: eri.bet.80@gmail.com | L40: PARTIDOS DEL GRAN BUENOS AIRES-NORTE | M40: San Gabriel | N40: 35 | O40: 6º Secundaria (Prov.) / 5º Media (CABA) | P40: 1 | Q40: 1 | R40: 90 | T40: Si | U40: No | V40: Jornada simple: sólo turno mañana (9:00 a 12.30 hs.) | W40: Miércoles 24/4 | AR40: Si | AS40: Si | AT40: Si | AU40: Si | AV40: Si | AW40: Si | AX40: Si | AY40: Si | AZ40: Si | BA40: Si | BB40: Si | BC40: Si | BD40: Si | BG40: Si | BH40: Si | BI40: Si
...

Sheet CRUDO MARTES
A1: Marca temporal | B1: Dirección de correo electrónico | C1: Nombre OFICIAL y COMPLETO de la institución educativa | D1: Código Único de Escuela (CUE) | E1: Tipo de escuela y orientación | F1: Especifique su orientación | G1: Gestión | H1: Nombre y apellido del/la docente responsable de la visita | I1: Nombre y apellido del/la docente acompañante 1 | J1: Nombre y apellido del/la docente acompañante 2 | K1: Dirección de correo electrónico para recibir resultado de la asignación | L1: Ubicación general de la escuela | M1: Barrio/Localidad de la escuela | N1: Cantidad de alumnos que asistirán | O1: Curso que asistirá | P1: Conectividad en la institución | Q1: Acceso a las ciencias exactas y naturales | R1: Porcentaje aproximado de estudiantes de familias de bajos recursos | S1: Exprese observaciones o comentarios que considere pertinentes | T1: Turno/s solicitado/s [Turno mañana (9:00 a 12.30 hs.)] | U1: Turno/s solicitado/s [Turno tarde (12.30 a 16:00 hs.)] | V1: Fecha solicitada | W1: CHARLAS [9:30 ] | X1: CHARLAS [10:30] | Y1: CHARLAS [11:30 ] | Z1: CHARLAS [14:00 ] | AA1: ESTACIONES INTERACTIVAS [9:30] | AB1: ESTACIONES INTERACTIVAS [10:30] | AC1: ESTACIONES INTERACTIVAS [11:30] | AD1: ESTACIONES INTERACTIVAS [13:00] | AE1: ESTACIONES INTERACTIVAS [14:00] | AF1: ESTACIONES INTERACTIVAS [15:00] | AG1: TALLERES [9:30] | AH1: TALLERES [10:30] | AI1: TALLERES [11:30] | AJ1: TALLERES [14:00] | AK1: TALLERES [15:00] | AL1: VISITAS GUIADAS TEMÁTICAS [10:30] | AM1: VISITAS GUIADAS TEMÁTICAS [11:30] | AN1: VISITAS GUIADAS TEMÁTICAS [14:00] | AO1: VISITAS GUIADAS TEMÁTICAS [15:00] | AP1: Exprese cualquier aclaración sobre la solicitud de inscripción que facilite la administración de vacantes. | AQ1: CHARLAS [9:30 ] | AR1: CHARLAS [10:30] | AS1: CHARLAS [11:30 ] | AT1: CHARLAS [14:00 ] | AU1: ESTACIONES INTERACTIVAS [9:30] | AV1: ESTACIONES INTERACTIVAS [10:30] | AW1: ESTACIONES INTERACTIVAS [11:30] | AX1: ESTACIONES INTERACTIVAS [13:00] | AY1: ESTACIONES INTERACTIVAS [14:00] | AZ1: ESTACIONES INTERACTIVAS [15:00] | BA1: TALLERES [9.30] | BB1: TALLERES [10:30] | BC1: TALLERES [11:30] | BD1: TALLERES [14:00] | BE1: TALLERES [15:00] | BF1: VISITA GUIADA [10:30] | BG1: VISITA GUIADA [11:30] | BH1: VISITA GUIADA [14:00] | BI1: VISITA GUIADA [15:00] | BJ1: Exprese cualquier aclaración sobre la solicitud de inscripción que facilite la administración de vacantes. | BK1: CHARLAS [9:30 ] | BL1: CHARLAS [10:30] | BM1: CHARLAS [11:30 ] | BN1: CHARLAS [14:00 ] | BO1: ESTACIONES INTERACTIVAS [9:30] | BP1: ESTACIONES INTERACTIVAS [10:30] | BQ1: ESTACIONES INTERACTIVAS [11:30] | BR1: ESTACIONES INTERACTIVAS [13:00] | BS1: ESTACIONES INTERACTIVAS [14:00] | BT1: ESTACIONES INTERACTIVAS [15:00] | BU1: TALLERES [9:30] | BV1: TALLERES [10:30 ] | BW1: TALLERES [11:30] | BX1: TALLERES [14:00] | BY1: TALLERES [15:00] | BZ1: VISITA GUIADA [10:30] | CA1: VISITA GUIADA [11:30] | CB1: VISITA GUIADA [14:00] | CC1: VISITA GUIADA [15:00] | CD1: Exprese cualquier aclaración sobre la solicitud de inscripción que facilite la administración de vacantes.
A2: 45363.438 | B2: candelaldana@gmail.com | C2: INSTITUTO SAN LUIS GONZAGA | D2: 061107100 | E2: 10. Liceos / Normales / Colegios / Institutos de otras orientaciones | F2: Economia y Administración. | G2: Privada | H2: Candela Aldana Lorusso | I2: Aun no están definidos los profesores acompañantes | J2: Aun no están definidos los profesores acompañantes | K2: candelaldana@gmail.com | L2: PARTIDOS DEL GRAN BUENOS AIRES-OESTE | M2: Tapiales / La Matanza | N2: 33 | O2: 6º Secundaria (Prov.) / 5º Media (CABA) | P2: 2 | Q2: 4 | R2: 50 | T2: Si | U2: No | V2: Martes 23/4 | W2: Si | X2: No | Y2: No | Z2: No | AA2: No | AB2: Si | AC2: No | AD2: No | AE2: No | AF2: No | AG2: No | AH2: No | AI2: Si | AJ2: No | AK2: No | AL2: No | AM2: No | AN2: No | AO2: No
A3: 45363.441 | B3: candelaldana@gmail.com | C3: INSTITUTO SAN LUIS GONZAGA | D3: 061107100 | E3: 10. Liceos / Normales / Colegios / Institutos de otras orientaciones | F3: Economía y administración | G3: Privada | H3: Candela Aldana Lorusso | I3: Aun no están determinados los profesores acompañantes | J3: Aun no están determinados los profesores acompañantes | K3: candelaldana@gmail.com | L3: PARTIDOS DEL GRAN BUENOS AIRES-OESTE | M3: Tapiales / La Matanza | N3: 32 | O3: 6º Secundaria (Prov.) / 5º Media (CABA) | P3: 2 | Q3: 4 | R3: 50 | T3: Si | U3: No | V3: Martes 23/4 | W3: Si | X3: No | Y3: No | Z3: No | AA3: No | AB3: Si | AC3: No | AD3: No | AE3: No | AF3: No | AG3: No | AH3: No | AI3: Si | AJ3: No | AK3: No | AL3: No | AM3: No | AN3: No | AO3: No
A4: 45363.443 | B4: candelaldana@gmail.com | C4: INSTITUTO SAN LUIS GONZAGA | D4: 061107100 | E4: 10. Liceos / Normales / Colegios / Institutos de otras orientaciones | F4: Comunicaciones | G4: Privada | H4: Candela Aldana Lorusso | I4: Aun no están determinados los profesores acompañantes | J4: Aun no están determinados los profesores acompañantes | K4: candelaldana@gmail.com | L4: PARTIDOS DEL GRAN BUENOS AIRES-OESTE | M4: Tapiales / La Matanza | N4: 31 | O4: 6º Secundaria (Prov.) / 5º Media (CABA) | P4: 2 | Q4: 4 | R4: 50 | T4: Si | U4: No | V4: Martes 23/4 | W4: Si | X4: No | Y4: No | Z4: No | AA4: No | AB4: Si | AC4: No | AD4: No | AE4: No | AF4: No | AG4: No | AH4: No | AI4: Si | AJ4: No | AK4: No | AL4: No | AM4: No | AN4: No | AO4: No
A5: 45363.475 | B5: santiagoandreanoemi@gmail.com | C5: Escuela de Educación Secundaria N° 3 Profeso Francisco J Salustio Quilmes | D5: 061000200 | E5: 1. Liceos / Normales / Colegios / Institutos orientados en ciencias naturales y/o exactas | F5: Ciencias Naturales | G5: Estatal | H5: Andrea Santiago | I5: Gabriela Cortés | J5: Jorge Domeneguini | K5: santiagoandreanoemi@gmail.com | L5: PARTIDOS DEL GRAN BUENOS AIRES-SUR | M5: Quilmes Oeste | N5: 35 | O5: 6º Secundaria (Prov.) / 5º Media (CABA) | P5: 2 | Q5: 2 | R5: 90 | T5: Si | U5: Si | V5: Martes 23/4 | W5: Si | X5: Si | Y5: Si | Z5: Si | AA5: No | AB5: No | AC5: No | AD5: No | AE5: No | AF5: No | AH5: Si | AO5: Si
A6: 45363.491 | B6: fbillone@lasnieves.edu.ar | C6: Nuestra señora de las nieves | D6: 020073800 | E6: 1. Liceos / Normales / Colegios / Institutos orientados en ciencias naturales y/o exactas | F6: Naturales | G6: Privada | H6: Florencia billone | I6: Mariana Ceraolo | K6: fbillone@lasnieves.edu.ar | L6: CABA | M6: Liniers | N6: 21 | O6: 5º Secundaria (Prov.) / 4º Media (CABA) | P6: 5 | Q6: 4 | R6: 0 | T6: Si | U6: No | V6: Martes 23/4 | W6: Si | X6: Si | Y6: Si | Z6: No | AA6: Si | AB6: Si | AC6: Si | AD6: No | AE6: No | AF6: No | AG6: Si | AH6: Si | AI6: Si | AJ6: No | AK6: No | AL6: Si | AM6: Si | AN6: No | AO6: No
A7: 45363.518 | B7: rominasanchez@njypater.com | C7: Instituto Pater c.e. | D7: 061933100 | E7: 1. Liceos / Normales / Colegios / Institutos orientados en ciencias naturales y/o exactas | F7: Sociales y economia | G7: Privada | H7: Romina Sanchez | I7: Gisela Marino | J7: Pablo Godoi | K7: rominasanchez@njypater.com | L7: PARTIDOS DEL GRAN BUENOS AIRES-SUR | M7: Bernal Quilmes | N7: 20 | O7: 5º Secundaria (Prov.) / 4º Media (CABA) | P7: 4 | Q7: 2 | R7: 20 | T7: Si | U7: No | V7: Martes 23/4 | W7: No | X7: No | Y7: Si | Z7: No | AA7: Si | AB7: Si | AC7: Si | AD7: Si | AE7: No | AF7: No | AG7: No | AH7: Si | AI7: No | AJ7: No | AK7: No | AL7: No | AM7: Si | AN7: No | AO7: No | AP7: Los alumnos realizan un proyecto sobre mate juegos y vendría genial! Gracias!
A8: 45363.521 | B8: secundaria@santiagoapostol.edu.ar | C8: Instituto Argentino Gallego Santiago Apóstol | D8: 020212700 | E8: 10. Liceos / Normales / Colegios / Institutos de otras orientaciones | F8: Bachiller con Orientación en ciencias sociales y humanidades | G8: Privada | H8: Rodriguez Bibiana | I8: Da Silva Rocio | K8: secundaria@santiagoapostol.edu.ar | L8: CABA | M8: Once | N8: 23 | O8: 6º Secundaria (Prov.) / 5º Media (CABA) | P8: 4 | Q8: 3 | R8: 0 | T8: Si | U8: No | V8: Martes 23/4 | W8: No | X8: Si | Y8: No | Z8: No | AA8: Si | AB8: No | AC8: No | AD8: No | AE8: No | AF8: Si | AG8: No | AH8: No | AI8: Si | AJ8: No | AK8: No | AL8: No | AM8: No | AN8: Si | AO8: No
A9: 45363.523 | B9: secundario@santiagoapostol.edu.ar | C9: Instituto Argentino Gallego Santiago Apóstol | D9: 020212700 | E9: 9. Liceos / Normales / Colegios / Institutos orientados en ciencias sociales y/o humanidades | F9: Bachiller con Orientación en Ciencias Sociales y Humanidades | G9: Privada | H9: Rodriguez Bibiana | I9: Rocio Da Silva | J9: Diego Colombo | K9: secundaria@santiagoapostol.edu.ar | L9: CABA | M9: Once | N9: 20 | O9: 5º Secundaria (Prov.) / 4º Media (CABA) | P9: 4 | Q9: 2 | R9: 0 | S9: Hicimos otra respuesta para poder ir con 4º y 5º año | T9: Si | U9: No | V9: Martes 23/4 | W9: No | X9: Si | Y9: No | Z9: No | AA9: Si | AB9: No | AC9: No | AD9: No | AE9: No | AF9: Si | AG9: No | AH9: No | AI9: Si | AJ9: No | AK9: No | AL9: No | AM9: No | AN9: Si | AO9: No | AP9: Hicimos dos formularios para ir con nuestros estudiantes de 4º y 5º año
A10: 45363.525 | B10: rominasanchez@njypater.com | C10: Instituto Pater c.e. | D10: 061933100 | E10: 1. Liceos / Normales / Colegios / Institutos orientados en ciencias naturales y/o exactas | F10: Sociales y Economia | G10: Privada | H10: Gisela Marino | I10: Romina Sanchez | J10: Pablo Godoi | K10: rominasanchez@njypater.com | L10: PARTIDOS DEL GRAN BUENOS AIRES-SUR | M10: Bernal Quilmes | N10: 35 | O10: 5º Secundaria (Prov.) / 4º Media (CABA) | P10: 4 | Q10: 2 | R10: 20 | T10: Si | U10: No | V10: Martes 23/4 | W10: No | X10: Si | Y10: No | Z10: No | AA10: Si | AB10: Si | AC10: Si | AD10: Si | AE10: No | AF10: No | AG10: No | AH10: Si | AI10: Si | AJ10: No | AK10: No | AL10: Si | AM10: No | AN10: No | AO10: No | AP10: Los estudiantes harán un proyecto sobre mate juegos vendría genial esta visita! Gracias
A11: 45363.543 | B11: jvibanez13@gmail.com | C11: Instituto Mercedes Pacheco | D11: 020029500 | E11: 9. Liceos / Normales / Colegios / Institutos orientados en ciencias sociales y/o humanidades | F11: Humanidades | G11: Privada | H11: Jorge Ibañez | I11: Luciana Perea | K11: jvibanez13@gmail.com | L11: CABA | M11: Recoleta | N11: 35 | O11: 6º Secundaria (Prov.) / 5º Media (CABA) | P11: 2 | Q11: 2 | R11: 5 | T11: No | U11: Si | V11: Martes 23/4 | W11: No | X11: No | Y11: No | Z11: Si | AA11: No | AB11: No | AC11: No | AD11: No | AE11: No | AF11: Si | AG11: No | AH11: No | AI11: No | AJ11: Si | AK11: Si | AL11: No | AM11: No | AN11: Si | AO11: Si | AP11: Nunca participamos
A12: 45363.555 | B12: auniversidad@goethe.edu.ar | C12: Instituto Escolar Goethe Schule | D12: 061215200 | E12: 1. Liceos / Normales / Colegios / Institutos orientados en ciencias naturales y/o exactas | F12: Ciencias Naturales | G12: Privada | H12: Tatiana Wolff | I12: Melina Seinfert | K12: auniversidad@goethe.edu.ar | L12: PARTIDOS DEL GRAN BUENOS AIRES-NORTE | M12: Boologne Sur Mer | N12: 25 | O12: 6º Secundaria (Prov.) / 5º Media (CABA) | P12: 5 | Q12: 5 | R12: 0 | T12: Si | U12: Si | V12: Martes 23/4 | W12: No | X12: Si | Y12: Si | Z12: No | AA12: Si | AB12: No | AC12: No | AD12: No | AE12: No | AF12: Si | AG12: No | AH12: No | AI12: Si | AJ12: Si | AK12: Si | AL12: No | AM12: No | AN12: No | AO12: No
A13: 45363.631 | B13: jessicaamaidana@gmail.com | C13: Instituto Educacional Argentino Nuestra Señora de Luján | D13: 20059400 | E13: 3. Técnicas en administración de empresas, administración de las organizaciones, servicios turísticos, multimedios | F13: Economía | G13: Privada | H13: Maidana Jessica | I13: Fenando beitia | J13: Fernanda goldaracena | K13: jessicaamaidana@gmail.com | L13: CABA | M13: Villa Pueyrredón | N13: 31 | O13: 6º Secundaria (Prov.) / 5º Media (CABA) | P13: 4 | Q13: 5 | R13: 30 | T13: Si | U13: No | V13: Martes 23/4 | W13: Si | X13: Si | Y13: Si | Z13: No | AA13: Si | AB13: Si | AC13: Si | AD13: No | AE13: No | AF13: No | AG13: Si | AH13: Si | AI13: Si | AJ13: No | AK13: No | AL13: Si | AM13: Si | AN13: No | AO13: No
A14: 45363.647 | B14: mercedesgonzalez@institutourquiza.edu.ar | C14: Instituto Justo José de Urquiza SRL | D14: 201342 | E14: 9. Liceos / Normales / Colegios / Institutos orientados en ciencias sociales y/o humanidades | F14: Comunicación | G14: Privada | H14: Mercedes Gonzalez | I14: Martín Volpatti | J14: Carlos Espósito | K14: mercedesgonzalez@institutourquiza.edu.ar | L14: CABA | M14: Caballito | N14: 20 | O14: 5º Secundaria (Prov.) / 4º Media (CABA) | P14: 4 | Q14: 1 | R14: 10 | T14: Si | U14: No | V14: Martes 23/4 | W14: Si | X14: Si | Y14: No | Z14: No | AA14: Si | AB14: Si | AC14: Si | AD14: No | AE14: No | AF14: No | AG14: Si | AH14: Si | AI14: Si | AJ14: No | AK14: No | AL14: Si | AM14: Si | AN14: No | AO14: No
A15: 45363.647 | B15: vanina.acuna89@gmail.com | C15: Instituto palomar de caseros | D15: 060578000 | E15: 9. Liceos / Normales / Colegios / Institutos orientados en ciencias sociales y/o humanidades | F15: Ciencias sociales | G15: Privada | H15: Vanina Acuña | I15: Claudia Cicarelli | J15: Leonardo Cardaci | K15: vanina.acuna89@gmail.com | L15: PARTIDOS DEL GRAN BUENOS AIRES-OESTE | M15: Ciudad jardin | N15: 25 | O15: 6º Secundaria (Prov.) / 5º Media (CABA) | P15: 3 | Q15: 3 | R15: 10 | T15: No | U15: Si | V15: Martes 23/4 | W15: No | X15: No | Y15: No | Z15: Si | AA15: No | AB15: No | AC15: No | AD15: Si | AE15: Si | AF15: Si | AG15: No | AH15: No | AI15: No | AJ15: Si | AK15: Si | AL15: No | AM15: No | AN15: Si | AO15: Si
A16: 45363.65 | B16: vanina.acuna89@gmail.com | C16: Instituto palomar de caseros | D16: 060578000 | E16: 10. Liceos / Normales / Colegios / Institutos de otras orientaciones | F16: Comunicaciones | G16: Privada | H16: Vanina acuña | I16: Claudia cicarelli | J16: Leonardo cardaci | K16: vanina.acuna89@gmail.com | L16: PARTIDOS DEL GRAN BUENOS AIRES-OESTE | M16: Ciudad jardin | N16: 20 | O16: 6º Secundaria (Prov.) / 5º Media (CABA) | P16: 3 | Q16: 3 | R16: 10 | T16: No | U16: Si | V16: Martes 23/4 | W16: No | X16: No | Y16: No | Z16: Si | AA16: No | AB16: No | AC16: No | AD16: Si | AE16: Si | AF16: Si | AG16: No | AH16: No | AI16: No | AJ16: Si | AK16: Si | AL16: No | AM16: No | AN16: Si | AO16: Si
A17: 45363.683 | B17: julieta.pianetti@bue.edu.ar | C17: ESC. TEC. Nº 30 NORBERTO PINERO DE 02 | D17: 020144800 | E17: 5. Técnicas área producción (electromecánica, mecánica, metalurgia, electricidad, automotores, refrigeración, construcciones, maestro mayor de obras, aeronáutica, naval, aviónico, óptico, en geografía matemática) | F17: Electromecánica | G17: Estatal | H17: Julieta Pianetti | I17: Gisela Martínez | J17: Alejandro Barrera | K17: julieta.pianetti@bue.edu.ar | L17: CABA | M17: Almagro | N17: 22 | O17: 5º Secundaria (Prov.) / 4º Media (CABA) | P17: 5 | Q17: 5 | R17: 90 | T17: Si | U17: No | V17: Martes 23/4 | W17: No | X17: No | Y17: No | Z17: No | AA17: Si | AB17: No | AC17: No | AD17: No | AE17: No | AF17: No | AG17: No | AH17: Si | AI17: No | AJ17: No | AK17: No | AL17: No | AM17: Si | AN17: No | AO17: No
A18: 45363.708 | B18: lucila.zobra@colegiosanfranciscocoll.com.ar | C18: COLEGIO SAN FRANCISCO COLL | D18: 020078500 | E18: 10. Liceos / Normales / Colegios / Institutos de otras orientaciones | F18: Economía y Administración | G18: Privada | H18: María Lucila Zobra | I18: Silvina Salvia | J18: Sofía Rodríguez Bazzi | K18: lucila.zobra@colegiosanfranciscocoll.com.ar | L18: CABA | M18: Villa Urquiza | N18: 35 | O18: 6º Secundaria (Prov.) / 5º Media (CABA) | P18: 2 | Q18: 3 | R18: 75 | T18: Si | U18: No | V18: Martes 23/4 | W18: Si | X18: No | Y18: No | Z18: No | AA18: No | AB18: Si | AC18: No | AD18: No | AE18: No | AF18: No | AG18: No | AH18: No | AI18: Si | AJ18: No | AK18: No | AL18: Si | AM18: No | AN18: No | AO18: No | AP18: No habría problema con modificar los horarios de talleres, actividades y charlas respetando día y turno.
A19: 45363.711 | B19: lucila.zobra@colegiosanfranciscocoll.com.ar | C19: COLEGIO SAN FRANCISCO COLL | D19: 020078500 | E19: 10. Liceos / Normales / Colegios / Institutos de otras orientaciones | F19: Economía y Administración | G19: Privada | H19: Lucila Zobra | I19: Cecilia Mota | J19: Macarena Sanguiao | K19: lucila.zobra@colegiosanfranciscocoll.com.ar | L19: CABA | M19: Villa Urquiza | N19: 35 | O19: 6º Secundaria (Prov.) / 5º Media (CABA) | P19: 2 | Q19: 3 | R19: 75 | T19: Si | U19: No | V19: Martes 23/4 | W19: Si | X19: No | Y19: No | Z19: No | AA19: No | AB19: Si | AC19: No | AD19: No | AE19: No | AF19: No | AG19: No | AH19: No | AI19: Si | AJ19: No | AK19: No | AL19: Si | AM19: No | AN19: No | AO19: No | AP19: No habría problema con modificar los horarios de talleres, actividades y charlas respetando día y turno.
A20: 45363.724 | B20: zelayaandrea@hotmail.com | C20: Instituto Don Orione | D20: 61338200 | E20: 1. Liceos / Normales / Colegios / Institutos orientados en ciencias naturales y/o exactas | F20: Naturales | G20: Privada | H20: Zelaya maria Andrea | I20: Glliozzi sandra | J20: SCHMITLEIN CLAUDIA | K20: zelayaandrea@hotmail.com | L20: PARTIDOS DEL GRAN BUENOS AIRES-SUR | M20: Florencio varela | N20: 30 | O20: 6º Secundaria (Prov.) / 5º Media (CABA) | P20: 5 | Q20: 5 | R20: 40 | S20: . | T20: Si | U20: No | V20: Martes 23/4 | W20: Si | X20: No | Y20: No | Z20: No | AA20: No | AB20: No | AC20: No | AD20: Si | AE20: No | AF20: No | AG20: No | AH20: Si | AJ20: No | AK20: No | AL20: No | AM20: Si | AN20: No | AO20: No
A21: 45363.727 | B21: zelayaandrea@hotmail.com | C21: Instituto Don Orione | D21: 61338200 | E21: 1. Liceos / Normales / Colegios / Institutos orientados en ciencias naturales y/o exactas | F21: Orientacion en Economía | G21: Privada | H21: Zelaya Maria Andrea | I21: Gliozzi Sandra | J21: Schmitlein claudia | K21: zelayaandrea@hotmail.com | L21: PARTIDOS DEL GRAN BUENOS AIRES-SUR | M21: Florencio Varela | N21: 30 | O21: 6º Secundaria (Prov.) / 5º Media (CABA) | P21: 5 | Q21: 5 | R21: 40 | S21: . | T21: Si | U21: Si | V21: Martes 23/4 | W21: Si | X21: No | Y21: No | Z21: No | AA21: No | AB21: No | AC21: No | AD21: Si | AE21: No | AF21: No | AG21: No | AH21: Si | AI21: No | AJ21: No | AK21: No | AL21: No | AM21: Si | AN21: No | AO21: No
A22: 45363.727 | B22: lilianamercado@colegioubaescobar.gob.ar | C22: Cereijo UBA | D22: 1111111 | E22: 1. Liceos / Normales / Colegios / Institutos orientados en ciencias naturales y/o exactas | F22: Exactas | G22: Estatal | H22: Liliana Mercado | I22: Marlene Aguirre | K22: lilianamercado@colegioubaescobar.gob.ar | L22: PARTIDOS DEL GRAN BUENOS AIRES-NORTE | M22: Belén de Escobar | N22: 35 | O22: 4º Secundaria (Prov:) / 3º Media (CABA) | P22: 5 | Q22: 5 | R22: 0 | T22: Si | U22: Si | V22: Martes 23/4 | W22: Si | X22: Si | Y22: Si | Z22: Si | AA22: Si | AB22: Si | AC22: Si | AD22: Si | AE22: No | AF22: No | AG22: Si | AL22: Si | AM22: Si
A23: 45363.73 | B23: lilianamercado@colegioubaescobar.gob.ar | C23: Cereijo UBA | D23: 1111111 | E23: 1. Liceos / Normales / Colegios / Institutos orientados en ciencias naturales y/o exactas | F23: Arte | G23: Estatal | H23: Liliana Mercado | I23: Sebastián Furlong | K23: lilianamercado@colegioubaescobar.gob.ar | L23: PARTIDOS DEL GRAN BUENOS AIRES-NORTE | M23: Belén de Escobar | N23: 35 | O23: 4º Secundaria (Prov:) / 3º Media (CABA) | P23: 5 | Q23: 5 | R23: 0 | T23: Si | U23: Si | V23: Martes 23/4 | W23: Si | X23: Si | Y23: Si | Z23: Si | AA23: Si | AB23: Si | AC23: Si | AD23: Si | AE23: Si | AF23: Si | AG23: Si | AH23: Si | AI23: Si | AJ23: Si | AK23: Si | AL23: Si | AM23: Si | AN23: Si | AO23: Si
A24: 45363.866 | B24: saulprofe2024@gmail.com | C24: Escuela de Educación Secundaria Nro 5 Belgrano Educador | D24: 060917900 | E24: 1. Liceos / Normales / Colegios / Institutos orientados en ciencias naturales y/o exactas | F24: Ciencias naturales y ciencias sociales | G24: Estatal | H24: Saúl Flores | I24: Walter Marquez | J24: Nadia Oflaerti | K24: saulprofe2024@gmail.com | L24: PARTIDOS DEL GRAN BUENOS AIRES-OESTE | M24: Campo de mayo | N24: 35 | O24: 6º Secundaria (Prov.) / 5º Media (CABA) | P24: 3 | Q24: 5 | R24: 40 | T24: No | U24: Si | V24: Martes 23/4 | W24: No | X24: No | Y24: No | Z24: No | AA24: No | AB24: No | AC24: No | AD24: Si | AE24: No | AF24: No | AJ24: Si | AO24: Si | AP24: No me deja marcar las opciones de visitaa guiadas y talleres.
A25: 45363.869 | B25: gisela.serrano@bue.edu.ar | C25: Escuela Normal Superior N°4 "Estanislao S. Zeballos" | D25: 20129700 | E25: 1. Liceos / Normales / Colegios / Institutos orientados en ciencias naturales y/o exactas | F25: Matemática-Física | G25: Estatal | H25: Gisela Serrano | I25: Natalia Grandal | J25: Yamile Bohorquez | K25: gisela.serrano@bue.edu.ar | L25: CABA | M25: Caballito | N25: 26 | O25: 6º Secundaria (Prov.) / 5º Media (CABA) | P25: 5 | Q25: 4 | R25: 10 | T25: Si | U25: No | V25: Martes 23/4 | W25: Si | X25: No | Y25: No | Z25: No | AA25: No | AB25: Si | AC25: No | AD25: No | AE25: No | AF25: No | AG25: No | AH25: No | AI25: Si | AJ25: No | AK25: No | AL25: No | AM25: No | AN25: No | AO25: No
A26: 45363.972 | B26: simonespinoza@colegiopiaget.edu.ar | C26: COLEGIO PIAGET | D26: 061222400 | E26: 4. Artísticas de todas las orientaciones | F26: Secundario orientación en artes | G26: Privada | H26: Magalí Garbuglia | I26: Gustavo Jaimes | J26: Simón Espinoza | K26: secundaria@colegiopiaget.edu.ar | L26: PARTIDOS DEL GRAN BUENOS AIRES-NORTE | M26: San Isidro | N26: 22 | O26: 5º Secundaria (Prov.) / 4º Media (CABA) | P26: 5 | Q26: 3 | R26: 0 | S26: Deseamos que nuestros estudiantes reconozcan la importancia de la matemática como disciplina transversal a todas | T26: Si | U26: Si | V26: Martes 23/4 | W26: Si | X26: Si | Y26: Si | Z26: No | AA26: Si | AB26: Si | AC26: Si | AD26: Si | AE26: Si | AF26: No | AG26: Si | AH26: Si | AI26: Si | AJ26: Si | AK26: No | AL26: Si | AM26: Si | AN26: No | AO26: No
A27: 45364.025 | B27: laurabusso@bue.edu.ar | C27: Normal 9 D. F. Sarmiento | D27: 00201177 | E27: 1. Liceos / Normales / Colegios / Institutos orientados en ciencias naturales y/o exactas | F27: Naturales y turismo | G27: Estatal | H27: María Laura Busso | I27: Gonzalo Godoy | J27: Lorena García | K27: laurabusso@bue.edu | L27: CABA | M27: Balvanera | N27: 35 | O27: 6º Secundaria (Prov.) / 5º Media (CABA) | P27: 3 | Q27: 3 | R27: 80 | S27: Poblacion escolar en su mayor parte del barrio de retiro | T27: Si | U27: No | V27: Martes 23/4 | W27: No | X27: No | Y27: Si | Z27: No | AA27: No | AB27: No | AC27: No | AD27: No | AE27: No | AF27: No | AG27: Si | AH27: No | AI27: No | AJ27: No | AK27: No | AL27: Si | AM27: No | AN27: No | AO27: No
A28: 45364.026 | B28: wmarquez@abc.gob.ar | C28: E.E.S n⁰5 "Belgrano Educador" | D28: 060917900 | E28: 1. Liceos / Normales / Colegios / Institutos orientados en ciencias naturales y/o exactas | F28: Exactas | G28: Estatal | H28: Walter Marquez | I28: Javier Delia | J28: Silvana Sosa | K28: wmarquez@abc.gob.ar | L28: PARTIDOS DEL GRAN BUENOS AIRES-OESTE | M28: San miguel | N28: 35 | O28: 6º Secundaria (Prov.) / 5º Media (CABA) | P28: 3 | Q28: 4 | R28: 40 | T28: Si | U28: Si | V28: Martes 23/4 | W28: No | X28: Si | Y28: Si | Z28: Si | AA28: No | AB28: Si | AC28: Si | AD28: Si | AE28: Si | AF28: Si | AG28: No | AH28: Si | AI28: Si | AJ28: Si | AK28: Si | AL28: Si | AM28: Si | AN28: Si | AO28: Si
A29: 45364.037 | B29: laurabusso@bue.edu.ar | C29: Normal 9 | D29: 201177 | E29: 1. Liceos / Normales / Colegios / Institutos orientados en ciencias naturales y/o exactas | F29: Turismo y naturales | G29: Estatal | H29: María Laura Busso | I29: Gonzalo Godoy | J29: Lorena García | K29: laurabusso@bue.edu.ar | L29: CABA | M29: Balvanera | N29: 35 | O29: 6º Secundaria (Prov.) / 5º Media (CABA) | P29: 3 | Q29: 3 | R29: 85 | T29: Si | U29: No | V29: Martes 23/4 | W29: No | X29: No | Y29: Si | Z29: No | AA29: No | AB29: No | AC29: No | AD29: No | AE29: No | AF29: No | AG29: Si | AH29: No | AI29: No | AJ29: No | AK29: No | AL29: No | AM29: Si | AN29: No | AO29: No
A30: 45364.391 | B30: marucha1673@gmail.com | C30: INSTITUTO EDUCACIONAL ARGENTINO NUESTRA SEÑORA DE LUJAN | D30: 61 | E30: 10. Liceos / Normales / Colegios / Institutos de otras orientaciones | F30: Informática | G30: Privada | H30: LAUTARO | I30: PEREYRA LIMA | J30: Fernanda Goldaracena | K30: maru.cuba73@gmail.com | L30: CABA | M30: Vila Pueyrredon | N30: 35 | O30: 6º Secundaria (Prov.) / 5º Media (CABA) | P30: 4 | Q30: 4 | R30: 10 | T30: Si | U30: No | V30: Martes 23/4 | W30: Si | X30: Si | Y30: No | Z30: No | AA30: Si | AB30: Si | AC30: Si | AD30: Si | AE30: No | AF30: No | AG30: Si | AH30: Si | AI30: Si | AJ30: No | AK30: No | AL30: Si | AM30: Si | AN30: No | AO30: No
