Workbook

Sheet Respuestas de formulario 1
A1: Marca temporal | B1: Dirección de correo electrónico | C1: Nombre OFICIAL y COMPLETO de la institución educativa | D1: codigo unico de escuela (cue) | E1: tipo de institucion educativa y orientacion | F1: Especifique su orientación | G1: tipo de gestion de la institucion educativa | H1: apellido y nombre del/la docente responsable de la visita | I1: Nombre y apellido del/la docente acompañante 1 | J1: Nombre y apellido del/la docente acompañante 2 | K1: Dirección de correo electrónico para recibir resultado de la asignación | L1: ubicacion de la escuela | M1: Barrio/Localidad de la escuela | N1: cantidad de alumnos que asistiran | O1: curso que asistira | P1: Conectividad en la institución | Q1: Acceso a las ciencias exactas y naturales | R1: porcentaje aproximado de estudiantes de familias de bajos recursos | S1: Exprese observaciones o comentarios que considere pertinentes | T1: Turno/s solicitado/s [Turno mañana (9:00 a 12.30 hs.)] | U1: Turno/s solicitado/s [Turno tarde (12.30 a 16:00 hs.)] | V1: turno solicitado | W1: fecha solicitada | X1: CHARLAS [9:30 Redes sociales: la matemática detrás de los "influencers". Rocío Balderrama] | Y1: CHARLAS [11:30 La Biblio junto a... la calculadora. Historias que no hacen historia. Juan Carlos Pedraza] | Z1: CHARLAS [14:00 ¿Cómo hacer ciencia con Twitter? Sofía del Pozo] | AA1: ESTACIONES INTERACTIVAS [9:30] | AB1: ESTACIONES INTERACTIVAS [10:30] | AC1: ESTACIONES INTERACTIVAS [11:30] | AD1: ESTACIONES INTERACTIVAS [13:00] | AE1: ESTACIONES INTERACTIVAS [14:00] | AF1: ESTACIONES INTERACTIVAS [15:00] | AG1: TALLERES [9:30] | AH1: TALLERES [10:30] | AI1: TALLERES [11:30] | AJ1: TALLERES [14:00] | AK1: TALLERES [15:00] | AL1: ARTE MATEMÁTICO [9:30] | AM1: ARTE MATEMÁTICO [10:30] | AN1: ARTE MATEMÁTICO [11:30] | AO1: ARTE MATEMÁTICO [14:00] | AP1: ARTE MATEMÁTICO [15:00] | AQ1: VISITAS GUIADAS TEMÁTICAS [10:30] | AR1: VISITAS GUIADAS TEMÁTICAS [11:30] | AS1: VISITAS GUIADAS TEMÁTICAS [14:00] | AT1: VISITAS GUIADAS TEMÁTICAS [15:00] | AU1: Exprese cualquier aclaración sobre la solicitud de inscripción que facilite la administración de vacantes. | AV1: CHARLAS [9:30 Desorden ordenado, ¡qué caos es esto! Paula Kuna] | AW1: CHARLAS [11:30 ¿Tenés una idea para cambiar el mundo? Primero simulalo. Rodrigo Castro] | AX1: CHARLAS [14:00 Embaldosados Fractales. Ursula Molter] | AY1: ESTACIONES INTERACTIVAS [9:30] | AZ1: ESTACIONES INTERACTIVAS [10:30] | BA1: ESTACIONES INTERACTIVAS [11:30] | BB1: ESTACIONES INTERACTIVAS [13:00] | BC1: ESTACIONES INTERACTIVAS [14:00] | BD1: ESTACIONES INTERACTIVAS [15:00] | BE1: TALLERES [9.30] | BF1: TALLERES [10:30] | BG1: TALLERES [11:30] | BH1: TALLERES [14:00] | BI1: TALLERES [15:00] | BJ1: ARTE MATEMÁTICO [9:30] | BK1: ARTE MATEMÁTICO [10:30] | BL1: ARTE MATEMÁTICO [11:30] | BM1: ARTE MATEMÁTICO [14:00] | BN1: ARTE MATEMÁTICO [15:00] | BO1: VISITA GUIADA [10:30] | BP1: VISITA GUIADA [11:30] | BQ1: VISITA GUIADA [14:00] | BR1: VISITA GUIADA [15:00] | BS1: Exprese cualquier aclaración sobre la solicitud de inscripción que facilite la administración de vacantes. | BT1: CHARLAS [9:30 Geometría proyectiva, fotografía y la final del mundo. Charly Di Fiore] | BU1: CHARLAS [11:30 Detective de datos. Guillermo Solovey] | BV1: CHARLAS [14:00 Datos y deportes. Iván Monardo] | BW1: ESTACIONES INTERACTIVAS [9:30] | BX1: ESTACIONES INTERACTIVAS [10:30] | BY1: ESTACIONES INTERACTIVAS [11:30] | BZ1: ESTACIONES INTERACTIVAS [13:00] | CA1: ESTACIONES INTERACTIVAS [14:00] | CB1: ESTACIONES INTERACTIVAS [15:00] | CC1: TALLERES [9:30] | CD1: TALLERES [10:30 ] | CE1: TALLERES [11:30] | CF1: TALLERES [14:00] | CG1: TALLERES [15:00] | CH1: ARTE MATEMÁTICO [9:30] | CI1: ARTE MATEMÁTICO [10:30] | CJ1: ARTE MATEMÁTICO [11:30] | CK1: ARTE MATEMÁTICO [14:00] | CL1: ARTE MATEMÁTICO [15:00] | CM1: VISITA GUIADA [10:30] | CN1: VISITA GUIADA [11:30] | CO1: VISITA GUIADA [14:00] | CP1: VISITA GUIADA [15:00] | CQ1: Exprese cualquier aclaración sobre la solicitud de inscripción que facilite la administración de vacantes.
A2: 45006.451 | B2: sromio@colegioesquiu.edu.ar | C2: Instituto Esquiu Asociaciòn Civil | D2: 000200976 | E2: 10. Liceos / Normales / Colegios / Institutos de otras orientaciones | F2: Ciencias naturales | G2: Privada | H2: Luis Rovella | I2: Romio Sol | K2: sromio@colegioesquiu.edu.ar | L2: CABA | M2: Belgrano | N2: 19 | O2: 6º Secundaria (Prov.) / 5º Media (CABA) | P2: 5 | Q2: 5 | R2: 0 | T2: Si | U2: No | V2: Jornada simple: sólo turno mañana (9:00 a 12.30 hs.) | W2: Jueves 27/4 | BT2: Si | BU2: No | BV2: No | BW2: No | BX2: Si | BY2: Si | BZ2: No | CA2: No | CB2: No | CC2: No | CD2: Si | CE2: Si | CF2: No | CG2: No | CH2: No | CI2: No | CJ2: No | CK2: No | CL2: No | CM2: No | CN2: No | CO2: No | CP2: No
A3: 45006.454 | B3: sromio@colegioesquiu.edu.ar | C3: Instituto Esquiu Asociaxion civil | D3: 000200976 | E3: 10. Liceos / Normales / Colegios / Institutos de otras orientaciones | F3: Economia y administracion | G3: Privada | H3: Romio Sol | I3: Rovella Luis | K3: sromio@colegioesquiu.edu.ar | L3: CABA | M3: Belgrano | N3: 23 | O3: 6º Secundaria (Prov.) / 5º Media (CABA) | P3: 5 | Q3: 5 | R3: 0 | T3: Si | U3: No | V3: Jornada simple: sólo turno mañana (9:00 a 12.30 hs.) | W3: Jueves 27/4 | BT3: Si | BU3: No | BV3: No | BW3: No | BX3: Si | BY3: Si | BZ3: No | CA3: No | CB3: No | CC3: No | CD3: Si | CE3: Si | CF3: No | CG3: No | CH3: No | CI3: No | CJ3: No | CK3: No | CL3: No | CM3: No | CN3: No | CO3: No | CP3: No
A4: 45003.415 | B4: yesicagambino@cesfj.edu.ar | C4: CENTRO EDUCATIVO SAN FRANCISCO JAVIER (A-136) | D4: 020010000 | E4: 10. Liceos / Normales / Colegios / Institutos de otras orientaciones | F4: Bachiller con orientación en Economía y Administración | G4: Privada | H4: Yesica Paola Gambino | I4: Daniela Menzulio | J4: Marcos Cayol | K4: yesicagambino@cesfj.edu.ar | L4: CABA | M4: Palermo | N4: 15 | O4: 6º Secundaria (Prov.) / 5º Media (CABA) | P4: 3 | Q4: 2 | R4: 40 | S4: Se trata de un colegio parroquial con 100% de subvención estatal. | T4: No | U4: Si | V4: Jornada simple: sólo turno tarde (12.30 a 16:00 hs.) | W4: Jueves 27/4 | BT4: No | BU4: No | BV4: Si | BW4: No | BX4: No | BY4: No | BZ4: No | CA4: Si | CB4: Si | CC4: No | CD4: No | CE4: No | CF4: Si | CG4: Si | CH4: No | CI4: No | CJ4: No | CK4: Si | CL4: Si | CM4: No | CN4: No | CO4: Si | CP4: Si
A5: 45005.552 | B5: roberto.holub@philips.edu.ar | C5: ESCUELA TECNICA PHILIPS ARGENTINA | D5: 020012900 | E5: 5. Técnicas área producción (electromecánica, mecánica, metalurgia, electricidad, automotores, refrigeración, construcciones, maestro mayor de obras, aeronáutica, naval, aviónico, óptico, en geografía matemática) | F5: ELECTROMECANICA | G5: Privada | H5: ROBERTO HOLUB | I5: NATALIA GRIMALDI | J5: FACUNDO ALBERINO | K5: roberto.holub@philips.edu.ar | L5: CABA | M5: COLEGIALES | N5: 29 | O5: 5º Secundaria (Prov.) / 4º Media (CABA) | P5: 5 | Q5: 4 | R5: 0 | T5: Si | U5: No | V5: Jornada simple: sólo turno mañana (9:00 a 12.30 hs.) | W5: Jueves 27/4 | BT5: No | BU5: Si | BV5: No | BW5: No | BX5: Si | BY5: No | BZ5: No | CA5: No | CB5: No | CC5: Si | CD5: No | CE5: No | CF5: No | CG5: No | CH5: No | CI5: No | CJ5: No | CK5: No | CL5: No | CM5: No | CN5: No | CO5: No | CP5: No
A6: 45005.547 | B6: roberto.holub@philips.edu.ar | C6: ESCUELA TECNICA PHILIPS ARGENTINA | D6: 020012900 | E6: 5. Técnicas área producción (electromecánica, mecánica, metalurgia, electricidad, automotores, refrigeración, construcciones, maestro mayor de obras, aeronáutica, naval, aviónico, óptico, en geografía matemática) | F6: ELECTROMECANICA | G6: Privada | H6: ROBERTO HOLUB | I6: NATALIA GRIMALDI | J6: FACUNDO ALBERINO | K6: roberto.holub@philips.edu.ar | L6: CABA | M6: COLEGIALES | N6: 31 | O6: 6º Secundaria (Prov.) / 5º Media (CABA) | P6: 5 | Q6: 4 | R6: 0 | T6: Si | U6: No | V6: Jornada simple: sólo turno mañana (9:00 a 12.30 hs.) | W6: Miércoles 26/4 | AV6: No | AW6: Si | AX6: No | AY6: No | AZ6: Si | BA6: No | BB6: No | BC6: No | BD6: No | BE6: Si | BF6: No | BG6: No | BH6: No | BI6: No | BJ6: No | BK6: No | BL6: No | BM6: No | BN6: No | BO6: No | BP6: No | BQ6: No | BR6: No
A7: 45000.677 | B7: mavisonora@yahoo.com.ar | C7: Colegio 19 Luis Pasteur | D7: 020014300 | E7: 1. Liceos / Normales / Colegios / Institutos orientados en ciencias naturales y/o exactas | F7: Cs Naturales | G7: Estatal | H7: María Virginia Sóñora | I7: PAOLA ARENA | K7: mavisonora@yahoo.com.ar | L7: CABA | M7: Devoto | N7: 25 | O7: 5º Secundaria (Prov.) / 4º Media (CABA) | P7: 3 | Q7: 3 | R7: 80 | T7: Si | U7: No | V7: Jornada simple: sólo turno mañana (9:00 a 12.30 hs.) | W7: Miércoles 26/4 | AV7: No | AW7: Si | AX7: No | AY7: No | AZ7: No | BA7: No | BB7: Si | BC7: No | BD7: No
A8: 45000.68 | B8: mavisonora@yahoo.com.ar | C8: Colegio 19 Luis Pasteur | D8: 020014300 | E8: 1. Liceos / Normales / Colegios / Institutos orientados en ciencias naturales y/o exactas | F8: Cs naturales | G8: Estatal | H8: Mtía Virginia Soñora | I8: Paola Arena | J8: Daniela Bragnolo | K8: mavisonora@yahoo.com.ar | L8: CABA | M8: Devoto | N8: 25 | O8: 5º Secundaria (Prov.) / 4º Media (CABA) | P8: 3 | Q8: 3 | R8: 80 | T8: No | U8: Si | V8: Jornada simple: sólo turno tarde (12.30 a 16:00 hs.) | W8: Miércoles 26/4 | AV8: No | AW8: No | AX8: Si | AY8: No | AZ8: No | BA8: No | BB8: No | BC8: No | BD8: Si
A9: 45001.521 | B9: mariade.castro@bue.edu.ar | C9: Colegio N° 19 DE 17 "Luis Pasteur" | D9: 020014300 | E9: 1. Liceos / Normales / Colegios / Institutos orientados en ciencias naturales y/o exactas | F9: Naturales | G9: Estatal | H9: Ángeles Castro | I9: Verónica Marrano | K9: mariade.castro@bue.edu.ar | L9: CABA | M9: Villa Devoto | N9: 35 | O9: 6º Secundaria (Prov.) / 5º Media (CABA) | P9: 4 | Q9: 1 | R9: 50 | T9: No | U9: Si | V9: Jornada simple: sólo turno tarde (12.30 a 16:00 hs.) | W9: Jueves 27/4 | BT9: No | BU9: Si | BV9: Si | BW9: No | BX9: No | BY9: No | BZ9: Si | CA9: No | CB9: No | CC9: No | CD9: No | CE9: No | CF9: No | CG9: Si | CH9: No | CI9: No | CJ9: No | CK9: No | CL9: Si | CM9: No | CN9: No | CO9: No | CP9: Si
A10: 45005.865 | B10: barrioluis92@gmail.com | C10: ESC. DE COM. Nº 20 DR. JUAN AGUSTIN GARCIA DE 14 | D10: 020015900 | E10: 10. Liceos / Normales / Colegios / Institutos de otras orientaciones | F10: Comercial | G10: Estatal | H10: Luis Octavio Barrio | I10: Mirta Filgueira | K10: barrioluis92@gmail.com | L10: CABA | M10: Paternal | N10: 20 | O10: 6º Secundaria (Prov.) / 5º Media (CABA) | P10: 4 | Q10: 2 | R10: 40 | T10: Si | U10: No | V10: Jornada simple: sólo turno mañana (9:00 a 12.30 hs.) | W10: Miércoles 26/4 | AV10: Si | AW10: Si | AX10: No | AY10: Si | AZ10: Si | BA10: Si | BB10: No | BC10: No | BD10: No | BE10: Si | BF10: Si | BG10: Si | BH10: No | BI10: No | BJ10: No | BK10: No | BL10: No | BM10: No | BN10: No | BO10: Si | BP10: Si | BS10: Actividades prioritarias: 9:30: Desorden ordenado, ¡qué caos es esto! 10:30: ESTACIONES INTERACTIVAS 11:30: VISITA GUIADA
A11: 45006.503 | B11: dekergustavo@gmail.com | C11: Instituto La Candelaria | D11: 020017800 | E11: 10. Liceos / Normales / Colegios / Institutos de otras orientaciones | F11: Economía | G11: Privada | H11: Gustavo Deker | I11: Marcelo Collavino | J11: Soledad Deker | K11: dekergustavo@gmail.com | L11: CABA | M11: Floresta | N11: 35 | O11: 5º Secundaria (Prov.) / 4º Media (CABA) | P11: 3 | Q11: 3 | R11: 5 | T11: Si | U11: No | V11: Jornada simple: sólo turno mañana (9:00 a 12.30 hs.) | W11: Miércoles 26/4 | AV11: Si | AW11: Si | AX11: Si | AY11: Si | AZ11: Si | BA11: Si | BB11: Si | BC11: Si | BD11: Si | BE11: Si | BF11: Si | BG11: Si | BH11: Si | BI11: Si | BJ11: No | BK11: No | BL11: Si | BM11: No | BN11: No | BO11: No | BP11: No | BQ11: No | BR11: No
A12: 45003.486 | B12: romina.angulo@bue.edu.ar | C12: ESCUELA TECNICA Nº12 "LIBERTADOR GRAL. SAN MARTIN" | D12: 020050900 | E12: 2. Técnicas en computación, electrónica, informática | F12: ELECTRONICA | G12: Estatal | H12: ROMINA ANGULO | I12: MICAELA RODRIGUEZ | K12: romina.angulo@bue.edu.ar | L12: CABA | M12: RETIRO | N12: 17 | O12: 5º Secundaria (Prov.) / 4º Media (CABA) | P12: 3 | Q12: 3 | R12: 90 | T12: No | U12: Si | V12: Jornada simple: sólo turno tarde (12.30 a 16:00 hs.) | W12: Martes 25/4 | X12: No | Y12: No | Z12: Si | AA12: No | AB12: No | AC12: No | AD12: Si | AE12: No | AF12: No | AG12: No | AH12: No | AI12: No | AJ12: No | AK12: Si | AL12: No | AM12: No | AN12: No | AO12: Si | AP12: No | AQ12: No | AR12: No | AS12: No | AT12: No
A13: 45002.995 | B13: ceciliadiaz@docentes.sanmaron.edu.ar | C13: INSTITUTO SAN MARON | D13: 020056200 | E13: 9. Liceos / Normales / Colegios / Institutos orientados en ciencias sociales y/o humanidades | F13: Sociales y Humanidades | G13: Privada | H13: Cecilia Díaz | I13: Marcela Urbano | K13: ceciliadiaz@docentes.sanmaron.edu.ar | L13: CABA | M13: Retiro | N13: 25 | O13: 6º Secundaria (Prov.) / 5º Media (CABA) | P13: 4 | Q13: 3 | R13: 8 | T13: Si | U13: No | V13: Jornada simple: sólo turno mañana (9:00 a 12.30 hs.) | W13: Martes 25/4 | X13: Si | Y13: No | Z13: No | AA13: No | AB13: No | AC13: No | AD13: Si | AE13: No | AF13: No | AG13: No | AH13: Si | AI13: No | AJ13: No | AK13: No | AL13: No | AM13: No | AN13: Si | AO13: No | AP13: No | AQ13: No | AR13: No | AS13: No | AT13: No
A14: 45000.83 | B14: rodrical85@hotmail.com | C14: INSTITUTO COLEGIO DE NUESTRA SEÑORA | D14: 020056500 | E14: 10. Liceos / Normales / Colegios / Institutos de otras orientaciones | F14: Informática | G14: Privada | H14: Ana María Rodríguez | I14: Laura López | J14: Maria Esther Fabbro | K14: rodrical85@hotmail.com | L14: CABA | M14: San Nicolás | N14: 20 | O14: 6º Secundaria (Prov.) / 5º Media (CABA) | P14: 5 | Q14: 4 | R14: 10 | T14: Si | U14: No | V14: Jornada simple: sólo turno mañana (9:00 a 12.30 hs.) | W14: Jueves 27/4 | BT14: Si | BU14: No | BV14: No | BW14: No | BX14: No | BY14: Si | BZ14: No | CA14: No | CB14: No | CC14: No | CD14: Si | CE14: No | CF14: No | CG14: No | CH14: No | CI14: No | CJ14: No | CK14: No | CL14: No | CM14: No | CN14: No | CO14: No | CP14: No
A15: 45001.487 | B15: mbusso@huergo.edu.ar | C15: Instituto industrial Luis A. Huergo | D15: 020056800 | E15: 10. Liceos / Normales / Colegios / Institutos de otras orientaciones | F15: Artes | G15: Privada | H15: María Laura Busso | I15: Gabriela Tarcetti | J15: Carolina Ruggeri | K15: mbusso@huergo.edu.ar | L15: CABA | M15: San Telmo | N15: 32 | O15: 5º Secundaria (Prov.) / 4º Media (CABA) | P15: 4 | Q15: 4 | R15: 0 | T15: Si | U15: No | V15: Jornada simple: sólo turno mañana (9:00 a 12.30 hs.) | W15: Jueves 27/4 | BT15: Si | BU15: No | BV15: No | BW15: No | BX15: No | BY15: No | BZ15: No | CA15: No | CB15: No | CC15: No | CD15: Si | CE15: No | CF15: No | CG15: No | CH15: No | CI15: No | CJ15: Si | CK15: No | CL15: No | CM15: No | CN15: No | CO15: No | CP15: No
A16: 45001.489 | B16: mbusso@huergo.edu.ar | C16: Instituto Huergo | D16: 020056800 | E16: 10. Liceos / Normales / Colegios / Institutos de otras orientaciones | F16: Artes | G16: Privada | H16: María Laura Busso | I16: Gabriela Tarcetti | J16: Carolina Ruggeri | K16: mbusso@huergo.edu.ar | L16: CABA | M16: San Telmo | N16: 32 | O16: 5º Secundaria (Prov.) / 4º Media (CABA) | P16: 4 | Q16: 4 | R16: 0 | T16: Si | U16: No | V16: Jornada simple: sólo turno mañana (9:00 a 12.30 hs.) | W16: Jueves 27/4 | BT16: Si | BU16: No | BV16: No | BW16: No | BX16: No | BY16: No | BZ16: No | CA16: No | CB16: No | CC16: No | CD16: Si | CE16: No | CF16: No | CG16: No | CH16: No | CI16: No | CJ16: Si | CK16: No | CL16: No | CM16: No | CN16: No | CO16: No | CP16: No
A17: 45001.648 | B17: mbusso@huergo.edu.ar | C17: Instituto Huergo | D17: 020056800 | E17: 10. Liceos / Normales / Colegios / Institutos de otras orientaciones | F17: Artes | G17: Privada | H17: María Laura Busso | I17: Gabriela Tarcetti | J17: Carolina Ruggeri | K17: mbusso@huergo.edu.ar | L17: CABA | M17: San Telmo | N17: 30 | O17: 5º Secundaria (Prov.) / 4º Media (CABA) | P17: 4 | Q17: 4 | R17: 0 | S17: Consideramos interesantes las propuestas para lograr, con nuestros estudiantes destacar el vínculo entre la matemática y las artes | T17: Si | U17: No | V17: Jornada simple: sólo turno mañana (9:00 a 12.30 hs.) | W17: Jueves 27/4 | BT17: Si | BU17: No | BV17: No | BW17: No | BX17: No | BY17: No | BZ17: No | CA17: No | CB17: No | CC17: No | CD17: Si | CE17: No | CF17: No | CG17: No | CH17: No | CI17: No | CJ17: Si | CK17: No | CL17: No | CM17: No | CN17: No | CO17: No | CP17: No | CQ17: Consideramos interesantes las propuestas para lograr, con nuestros estudiantes, destacar el vínculo entre la matemática y las artes.
A18: 45004.571 | B18: fbeitia@hotmail.com | C18: INST.EDUC.ARG.NTRA.SRA.DE LUJAN | D18: 020059400 | E18: 10. Liceos / Normales / Colegios / Institutos de otras orientaciones | F18: Bachillerato con orientación en Comunicación Social | G18: Privada | H18: Fernando Beitia | I18: Fernanda Goldaracena | J18: Jéssica Maidana | K18: fbeitia@hotmail.com | L18: CABA | M18: Villa Pueyrredón | N18: 34 | O18: 6º Secundaria (Prov.) / 5º Media (CABA) | P18: 4 | Q18: 4 | R18: 15 | T18: Si | U18: No | V18: Jornada simple: sólo turno mañana (9:00 a 12.30 hs.) | W18: Martes 25/4 | X18: Si | Y18: Si | Z18: No | AA18: No | AB18: Si | AC18: No | AD18: No | AE18: No | AF18: No | AG18: No | AH18: No | AI18: No | AJ18: No | AK18: No | AL18: No | AM18: No | AN18: No | AO18: No | AP18: No | AQ18: No | AR18: No | AS18: No | AT18: No
A19: 45004.573 | B19: fbeitia@hotmail.com | C19: INST.EDUC.ARG.NTRA.SRA.DE LUJAN | D19: 020059400 | E19: 10. Liceos / Normales / Colegios / Institutos de otras orientaciones | F19: Bachillerato con orientación en Economía y Administración | G19: Privada | H19: Jéssica Maidana | I19: Fernanda Goldaracena | J19: Fernando Beitia | K19: fbeitia@hotmail.com | L19: CABA | M19: Villa Pueyrredón | N19: 35 | O19: 6º Secundaria (Prov.) / 5º Media (CABA) | P19: 4 | Q19: 4 | R19: 15 | T19: Si | U19: No | V19: Jornada simple: sólo turno mañana (9:00 a 12.30 hs.) | W19: Martes 25/4 | X19: Si | Y19: Si | Z19: No | AA19: No | AB19: Si | AC19: No | AD19: No | AE19: No | AF19: No | AG19: No | AH19: Si | AI19: No | AJ19: No | AK19: No | AL19: No | AM19: No | AN19: No | AO19: No | AP19: No | AQ19: No | AR19: No | AS19: No | AT19: No
A20: 45004.575 | B20: fbeitia@hotmail.com | C20: INST.EDUC.ARG.NTRA.SRA.DE LUJAN | D20: 020059400 | E20: 10. Liceos / Normales / Colegios / Institutos de otras orientaciones | F20: Bachillerato con orientación en Informática | G20: Privada | H20: Jéssica Maidana | I20: Fernanda Goldaracena | J20: Fernando Beitia | K20: fbeitia@hotmail.com | L20: CABA | M20: Villa Pueyrredón | N20: 33 | O20: 6º Secundaria (Prov.) / 5º Media (CABA) | P20: 4 | Q20: 4 | R20: 15 | T20: Si | U20: No | V20: Jornada simple: sólo turno mañana (9:00 a 12.30 hs.) | W20: Martes 25/4 | X20: Si | Y20: Si | Z20: No | AA20: No | AB20: Si | AC20: No | AD20: No | AE20: No | AF20: No | AG20: No | AH20: Si | AI20: No | AJ20: No | AK20: No | AL20: No | AM20: Si | AN20: No | AO20: No | AP20: No | AQ20: No | AR20: Si | AS20: No | AT20: No
A21: 45001.806 | B21: magalimorelli@misericordia.edu.ar | C21: INST. NUESTRA SEÑORA DE LA MISERICORDIA | D21: 020067300 | E21: 9. Liceos / Normales / Colegios / Institutos orientados en ciencias sociales y/o humanidades | F21: Economía y Administración de Empresas / Comunicación | G21: Privada | H21: Magalí Morelli | I21: Andrea Mortati | J21: Luciana Perea | K21: magalimorelli@misericordia.edu.ar | L21: CABA | M21: Recoleta | N21: 29 | O21: 4º Secundaria (Prov:) / 3º Media (CABA) | P21: 3 | Q21: 3 | R21: 50 | S21: En lo posible que sea el jueves 27/04 que es el día que está la docente de Matemática a cargo del curso. | T21: Si | U21: No | V21: Jornada simple: sólo turno mañana (9:00 a 12.30 hs.) | W21: Jueves 27/4 | BT21: No | BU21: Si | BV21: Si | BW21: Si | BX21: Si | BY21: Si | BZ21: No | CA21: No | CB21: No | CC21: Si | CD21: Si | CE21: Si | CF21: No | CG21: No | CH21: Si | CI21: Si | CJ21: Si | CK21: No | CL21: No | CM21: No | CN21: No | CO21: No | CP21: No
A22: 45001.407 | B22: lucilazobra@beataimelda.org | C22: Instituto Beata Imelda | D22: 020067400 | E22: 9. Liceos / Normales / Colegios / Institutos orientados en ciencias sociales y/o humanidades | F22: Ciencias Sociales | G22: Privada | H22: Lucila Zobra | I22: Ariel Malatesta | J22: Andrea Chiola | K22: lucilazobra@beataimelda.org | L22: CABA | M22: Villa Urquiza | N22: 30 | O22: 5º Secundaria (Prov.) / 4º Media (CABA) | P22: 4 | Q22: 4 | R22: 20 | T22: Si | U22: No | V22: Jornada simple: sólo turno mañana (9:00 a 12.30 hs.) | W22: Jueves 27/4 | BT22: Si | BU22: No | BV22: No | BW22: No | BX22: Si | BY22: Si | BZ22: No | CA22: No | CB22: No | CC22: No | CD22: Si | CE22: Si | CF22: No | CG22: No | CH22: No | CI22: Si | CJ22: Si | CK22: No | CL22: No | CM22: No | CN22: No | CO22: No | CP22: No
A23: 45001.411 | B23: nivelsecundario@beataimelda.org | C23: Instituto Beata Imelda | D23: 020067400 | E23: 10. Liceos / Normales / Colegios / Institutos de otras orientaciones | F23: Economía y Administración | G23: Privada | H23: Andrea Chiola | I23: Lucila Zobra | J23: Ariel Malatesta | K23: nivelsecundario@beataimelda.org | L23: CABA | M23: Villa Urquiza | N23: 34 | O23: 5º Secundaria (Prov.) / 4º Media (CABA) | P23: 4 | Q23: 4 | R23: 10 | T23: Si | U23: No | V23: Jornada simple: sólo turno mañana (9:00 a 12.30 hs.) | W23: Jueves 27/4 | BT23: Si | BU23: No | BV23: No | BW23: No | BX23: Si | BY23: Si | BZ23: No | CA23: No | CB23: No | CC23: No | CD23: Si | CE23: Si | CF23: No | CG23: No | CH23: No | CI23: Si | CJ23: Si | CK23: No | CL23: No | CM23: No | CN23: No | CO23: No | CP23: No
A24: 45005.589 | B24: rosana.dionisio@bue.edu.ar | C24: ESC. DE COM. N° 33 MAIPU DE 18 -Prof Rosana Dionisio | D24: 020068000 | E24: 10. Liceos / Normales / Colegios / Institutos de otras orientaciones | F24: Administración y economía | G24: Estatal | H24: Dionisio Rosana | I24: Zarlenga Silvina | J24: Zambonini Verónica | K24: rosana.dionisio@bue.edu.ar | L24: CABA | M24: Monte Castro | N24: 35 | O24: 6º Secundaria (Prov.) / 5º Media (CABA) | P24: 4 | Q24: 4 | R24: 40 | T24: Si | U24: No | V24: Jornada simple: sólo turno mañana (9:00 a 12.30 hs.) | W24: Jueves 27/4 | BT24: Si | BU24: No | BV24: No | BW24: No | BX24: Si | BY24: No | BZ24: No | CA24: No | CB24: No | CC24: No | CD24: No | CE24: Si | CF24: No | CG24: No | CH24: No | CI24: No | CJ24: No | CK24: No | CL24: No | CM24: Si | CN24: Si | CO24: No | CP24: No
A25: 45001.751 | B25: valeria.shuman@bue.edu.ar | C25: Ens 6 Vicente Lopez y PlaneS | D25: 020071700 | E25: 1. Liceos / Normales / Colegios / Institutos orientados en ciencias naturales y/o exactas | F25: Matemática y Fisica | G25: Estatal | H25: Valeria Shuman | I25: Monica Robledo | J25: Kelly Dabek | K25: valeria.shuman@bue.edu.ar | L25: CABA | M25: Palermo | N25: 27 | O25: 6º Secundaria (Prov.) / 5º Media (CABA) | P25: 4 | Q25: 3 | R25: 60 | T25: Si | U25: No | V25: Jornada simple: sólo turno mañana (9:00 a 12.30 hs.) | W25: Miércoles 26/4 | AV25: Si | AW25: No | AX25: No | AY25: No | AZ25: Si | BA25: No | BB25: No | BC25: No | BD25: No | BE25: No | BF25: No | BG25: Si | BH25: No | BI25: No | BJ25: No | BK25: No | BL25: Si | BM25: No | BN25: No | BO25: No | BP25: No | BQ25: No | BR25: No
A26: 45005.822 | B26: r.estrella@instcristomaestro.edu.ar | C26: Instituto Cristo Maestro | D26: 020072300 | E26: 2. Técnicas en computación, electrónica, informática | F26: Bachiller en informática | G26: Privada | H26: Silvana Rocío Estrella | I26: Santiago Mollano | J26: Ana Bardauil | K26: r.estrella@instcristomaestro.edu.ar | L26: CABA | M26: CABA Floresta | N26: 25 | O26: 6º Secundaria (Prov.) / 5º Media (CABA) | P26: 4 | Q26: 3 | R26: 40 | T26: Si | U26: Si | V26: Jornada completa: turno completo (9:00 a 16.00 hs.) | W26: Jueves 27/4 | BT26: Si | BU26: Si | BV26: Si | BW26: No | BX26: Si | BY26: Si | BZ26: Si | CA26: Si | CB26: Si | CC26: No | CD26: Si | CE26: Si | CF26: Si | CG26: Si | CH26: No | CI26: Si | CJ26: Si | CK26: Si | CL26: Si | CM26: Si | CN26: Si | CO26: Si | CP26: Si | CQ26: Todo parece muy interesante , las propuestas con cupo serán enriquecedoras cual sea.
A27: 45002.545 | B27: secretaria.secundaria@sangregorio.edu.ar | C27: Instituto educativo san gregorio el iluminador | D27: 020074000 | E27: 10. Liceos / Normales / Colegios / Institutos de otras orientaciones | F27: Economía y administración | G27: Privada | H27: Adriana Margossian | I27: Adriana Maegossian | J27: Mariana Crespo | K27: secretaria.secundaria@sangregorio.edu.ar | L27: CABA | M27: Palermo | N27: 24 | O27: 6º Secundaria (Prov.) / 5º Media (CABA) | P27: 4 | Q27: 4 | R27: 30 | S27: A pesar de tener la orientación de economía y administración, tenes alumnos interesados en carreras de ciencias exactas y naturales, y desde las materias matematica y química y física fomentamos estas ciencias | T27: Si | U27: No | V27: Jornada simple: sólo turno mañana (9:00 a 12.30 hs.) | W27: Martes 25/4 | X27: Si | Y27: No | Z27: Si | AA27: No | AB27: Si | AC27: Si | AD27: No | AE27: No | AF27: No | AG27: No | AH27: Si | AI27: Si | AJ27: No | AK27: No | AL27: No | AM27: Si | AN27: Si | AO27: No | AP27: No | AQ27: Si | AR27: Si | AS27: No | AT27: No
A28: 45003.74 | B28: secretaria.secundaria@sangregorio.edu.ar | C28: instituto educativo san gregorio el iluminador | D28: 020074000 | E28: 10. Liceos / Normales / Colegios / Institutos de otras orientaciones | F28: Economía y administración | G28: Privada | H28: Adriana Margossian | I28: Adriana Margossian | J28: Mariana crespo | K28: secretaria.secundaria@sangregorio.edu.ar | L28: CABA | M28: Palermo | N28: 25 | O28: 6º Secundaria (Prov.) / 5º Media (CABA) | P28: 4 | Q28: 4 | R28: 30 | S28: A pesar de tener la orientación de economía y administración, tenes alumnos interesados en carreras de ciencias exactas y naturales, y desde las materias matematica y química y física fomentamos estas ciencias | T28: Si | U28: No | V28: Jornada simple: sólo turno mañana (9:00 a 12.30 hs.) | W28: Martes 25/4 | X28: Si | Y28: No | Z28: No | AA28: No | AB28: Si | AC28: Si | AD28: No | AE28: No | AF28: No | AG28: No | AH28: Si | AI28: Si | AJ28: No | AK28: No | AL28: No | AM28: Si | AN28: Si | AO28: No | AP28: No | AQ28: Si | AR28: Si | AS28: No | AT28: No
A29: 45001.377 | B29: mariaa.sosa@bue.edu.ar | C29: Liceo N° 01 Jose Figueroa Alcorta DE 02 | D29: 020074400 | E29: 1. Liceos / Normales / Colegios / Institutos orientados en ciencias naturales y/o exactas | F29: Ciencias Naturales y Exactas | G29: Estatal | H29: Jonathan España | I29: Maria Andrea Sosa | J29: Nicolas Lovece | K29: mariaa.sosa@bue.edu.ar | L29: CABA | M29: Barrio Norte | N29: 40 | O29: 6º Secundaria (Prov.) / 5º Media (CABA) | P29: 4 | Q29: 3 | R29: 80 | T29: Si | U29: Si | V29: Jornada completa: turno completo (9:00 a 16.00 hs.) | W29: Jueves 27/4 | BT29: Si | BU29: Si | BV29: Si | BW29: Si | BX29: Si | BY29: Si | BZ29: Si | CA29: Si | CB29: Si | CC29: Si | CD29: Si | CE29: Si | CF29: Si | CG29: Si | CH29: No | CI29: No | CJ29: No | CK29: No | CL29: No | CM29: Si | CN29: Si | CO29: Si | CP29: Si
A30: 45001.497 | B30: biblioteca@casasantacatalina.com.ar | C30: Instituto Privado Santa Catalina | D30: 020076800 | E30: 3. Técnicas en administración de empresas, administración de las organizaciones, servicios turísticos, multimedios | F30: Administracion | G30: Privada | H30: Paz Rozen | I30: Alicia Mendella | K30: biblioteca@casasantacatalina.com.ar | L30: CABA | M30: Constitucion | N30: 35 | O30: 6º Secundaria (Prov.) / 5º Media (CABA) | P30: 3 | Q30: 2 | R30: 20 | T30: Si | U30: No | V30: Jornada simple: sólo turno mañana (9:00 a 12.30 hs.) | W30: Martes 25/4 | X30: Si | Y30: Si | Z30: No | AA30: Si | AB30: Si | AC30: Si | AD30: No | AE30: No | AF30: No | AG30: Si | AH30: Si | AI30: Si | AJ30: No | AK30: No | AL30: Si | AM30: Si | AN30: Si | AO30: No | AP30: No | AQ30: Si | AR30: Si | AS30: No | AT30: No
A31: 45001.499 | B31: biblioteca@casasantacatalina.com.ar | C31: Instituto privado santa catalina | D31: 020076800 | E31: 10. Liceos / Normales / Colegios / Institutos de otras orientaciones | F31: comunicacion | G31: Privada | H31: paz rozen | I31: alicia mendella | K31: biblioteca@casasantacatalina.com.ar | L31: CABA | M31: constitcion | N31: 35 | O31: 6º Secundaria (Prov.) / 5º Media (CABA) | P31: 3 | Q31: 2 | R31: 20 | T31: Si | U31: No | V31: Jornada simple: sólo turno mañana (9:00 a 12.30 hs.) | W31: Jueves 27/4 | BT31: Si | BU31: Si | BV31: No | BW31: Si | BX31: Si | BY31: Si | BZ31: No | CA31: No | CB31: No | CC31: Si | CD31: Si | CE31: Si | CF31: No | CG31: No | CH31: Si | CI31: Si | CJ31: Si | CK31: No | CL31: No | CM31: Si | CN31: Si | CO31: No | CP31: No
A32: 45002.34 | B32: biblioteca@casasantacatalina.com.ar | C32: Instituto privado santa catalina | D32: 020076800 | E32: 10. Liceos / Normales / Colegios / Institutos de otras orientaciones | F32: Economía y Administración | G32: Privada | H32: Paz Rozen | I32: Alicia Mendella | K32: biblioteca@casasantacatalina.com.ar | L32: CABA | M32: Constitucion | N32: 35 | O32: 6º Secundaria (Prov.) / 5º Media (CABA) | P32: 3 | Q32: 2 | R32: 20 | S32: Este formulario lo complete ayer pero confundi la orientacion del curso. Puse Técnicas en administración de empresas, administración de las organizaciones, servicios turísticos, multimedios en lugar de 10. Liceos / Normales / Colegios / Institutos de otras orientaciones, mil disculpas. | T32: Si | U32: No | V32: Jornada simple: sólo turno mañana (9:00 a 12.30 hs.) | W32: Martes 25/4 | X32: Si | Y32: Si | Z32: No | AA32: Si | AB32: Si | AC32: Si | AD32: No | AE32: No | AF32: No | AG32: Si | AH32: Si | AI32: Si | AJ32: No | AK32: No | AL32: Si | AM32: Si | AN32: Si | AO32: No | AP32: No | AQ32: Si | AR32: Si | AS32: No | AT32: No
A33: 45002.736 | B33: lulizobra@gmail.com | C33: Colegio San Francisco Coll | D33: 020078500 | E33: 10. Liceos / Normales / Colegios / Institutos de otras orientaciones | F33: Economía y Administración | G33: Privada | H33: Lucila Zobra | I33: Silvina Salvia | J33: Macarena Sanguiao | K33: lulizobra@gmail.com | L33: CABA | M33: Villa Urquiza | N33: 31 | O33: 6º Secundaria (Prov.) / 5º Media (CABA) | P33: 4 | Q33: 4 | R33: 25 | T33: Si | U33: No | V33: Jornada simple: sólo turno mañana (9:00 a 12.30 hs.) | W33: Martes 25/4 | X33: Si | Y33: No | Z33: No | AA33: No | AB33: Si | AC33: Si | AD33: No | AE33: No | AF33: No | AG33: No | AH33: Si | AI33: Si | AJ33: No | AK33: No | AL33: No | AM33: Si | AN33: Si | AO33: No | AP33: No | AQ33: No | AR33: No | AS33: No | AT33: No
A34: 45002.738 | B34: sfc.lucilazobra@gmail.com | C34: Colegio San Francisco Coll | D34: 020078500 | E34: 10. Liceos / Normales / Colegios / Institutos de otras orientaciones | F34: Economía y Administración | G34: Privada | H34: Lucila Zobra | I34: Silvina Salvia | J34: Macarena Sanguiao | K34: sfc.lucilazobra@gmail.com | L34: CABA | M34: Villa Urquiza | N34: 34 | O34: 6º Secundaria (Prov.) / 5º Media (CABA) | P34: 4 | Q34: 4 | R34: 25 | T34: Si | U34: No | V34: Jornada simple: sólo turno mañana (9:00 a 12.30 hs.) | W34: Martes 25/4 | X34: Si | Y34: No | Z34: No | AA34: No | AB34: Si | AC34: Si | AD34: No | AE34: No | AF34: No | AG34: No | AH34: Si | AI34: Si | AJ34: No | AK34: No | AL34: No | AM34: Si | AN34: Si | AO34: No | AP34: No | AQ34: No | AR34: No | AS34: No | AT34: No
A35: 45001.757 | B35: carla.spazzali@gmail.com | C35: Instituto Santa María de Nazareth | D35: 020082200 | E35: 10. Liceos / Normales / Colegios / Institutos de otras orientaciones | F35: economía y comunicación | G35: Privada | H35: Carla | I35: Spazzali | J35: Belen Gonzalez | K35: carla.spazzali@gmail.com | L35: CABA | M35: saavedra | N35: 40 | O35: 6º Secundaria (Prov.) / 5º Media (CABA) | P35: 3 | Q35: 3 | R35: 5 | T35: Si | U35: No | V35: Jornada simple: sólo turno mañana (9:00 a 12.30 hs.) | W35: Martes 25/4 | X35: Si | Y35: Si | Z35: No | AA35: Si | AB35: Si | AC35: Si | AD35: No | AE35: No | AF35: No | AG35: Si | AH35: Si | AI35: Si | AJ35: No | AK35: No | AL35: Si | AM35: Si | AN35: Si | AO35: No | AP35: No | AQ35: Si | AR35: Si | AS35: No | AT35: No
A36: 45000.67 | B36: morelli.nicolas.a@gmail.com | C36: Colegio Norbridge | D36: 020082300 | E36: 10. Liceos / Normales / Colegios / Institutos de otras orientaciones | F36: Economía y Administración | G36: Privada | H36: Nicolás Morelli | I36: Liliana Villena | J36: Alejandra Sánchez | K36: morelli.nicolas.a@gmail.com | L36: CABA | M36: Saavedra | N36: 36 | O36: 6º Secundaria (Prov.) / 5º Media (CABA) | P36: 4 | Q36: 4 | R36: 0 | S36: Llevamos todos los años a nuestro 5to año a la Semana De la Matemática y los estudiantes la disfrutan mucho! | T36: Si | U36: No | V36: Jornada simple: sólo turno mañana (9:00 a 12.30 hs.) | W36: Martes 25/4 | X36: Si | Y36: No | Z36: No | AA36: No | AB36: No | AC36: Si | AD36: No | AE36: No | AF36: No | AG36: No | AH36: No | AI36: No | AJ36: No | AK36: No | AL36: No | AM36: No | AN36: Si | AO36: No | AP36: No | AQ36: Si | AR36: No | AS36: No | AT36: No | AU36: Nos gustaría poder hacer la visita guiada ya que el año pasado no pudimos.
A37: 45001.528 | B37: nicolas.morelli@colegionorbridge.edu.ar | C37: Colegio Norbridge | D37: 020082300 | E37: 10. Liceos / Normales / Colegios / Institutos de otras orientaciones | F37: Economía y Administración | G37: Privada | H37: Nicolás Morelli | I37: Liliana Villena | J37: Analía Mezzelani | K37: nicolas.morelli@colegionorbridge.edu.ar | L37: CABA | M37: Saavedra | N37: 35 | O37: 6º Secundaria (Prov.) / 5º Media (CABA) | P37: 5 | Q37: 5 | R37: 0 | S37: Realicé una inscripción para el día martes, y por un problema de agenda de la Rectora me pidió cambiarlo a jueves. Pido por favor desestimar esa inscripción y tomar como válida esta. Vamos todos los años y los chicos disfrutan mucho la experiencia. Gracias por todo el trabajo! | T37: Si | U37: No | V37: Jornada simple: sólo turno mañana (9:00 a 12.30 hs.) | W37: Jueves 27/4 | BT37: Si | BU37: No | BV37: No | BW37: No | BX37: Si | BY37: No | BZ37: No | CA37: No | CB37: No | CC37: No | CD37: No | CE37: No | CF37: No | CG37: No | CH37: No | CI37: Si | CJ37: No | CK37: No | CL37: No | CM37: No | CN37: Si | CO37: No | CP37: No | CQ37: Pido si por favor podemos tener la visita guiada. El año pasado no pudimos tenerla y los chicos se quedaron con muchas ganas de hacerla. Muchas gracias.
A38: 45000.911 | B38: ariadna.rio@bue.edu.ar | C38: ESC. DE COM. Nº 11 DR JOSE PERALTA DE 17 | D38: 020085900 | E38: 10. Liceos / Normales / Colegios / Institutos de otras orientaciones | F38: economía | G38: Estatal | H38: Ariadna Rio | I38: Magdalena aguiar | K38: ariadna.rio@bue.edu.ar | L38: CABA | M38: Villa Devoto CABA | N38: 30 | O38: 5º Secundaria (Prov.) / 4º Media (CABA) | P38: 5 | Q38: 3 | R38: 40 | S38: El porcentaje es estimativo. No tengo los datos. Pero los estudiantes vienen mayormente del barrio ejército de los andes y ese porcentaje es el beneficiario de las becas. | T38: Si | U38: No | V38: Jornada simple: sólo turno mañana (9:00 a 12.30 hs.) | W38: Jueves 27/4 | BT38: Si | BU38: Si | BV38: No | BW38: No | BX38: Si | BY38: No | BZ38: No | CA38: No | CB38: No | CC38: No | CD38: No | CE38: Si | CF38: No | CG38: No | CH38: No | CI38: No | CJ38: Si | CK38: No | CL38: No | CM38: No | CN38: No | CO38: No | CP38: No | CQ38: Marcamos varias opciones porque nos gustan todas y para poder hacer alguna en el horario de 10:30 y otra en el de 11:30 dejamos a criterio de la disponibilidad que tengan
A39: 45003.55 | B39: nariv@misericordiadevoto.edu.ar | C39: Colegio Nuestra Señora de la Misericordia de devoto A-110 | D39: 020086000 | E39: 9. Liceos / Normales / Colegios / Institutos orientados en ciencias sociales y/o humanidades | F39: Humanidades y Cs. Sociales | G39: Privada | H39: Victoria Anahí Nari | I39: Maria Adriana Lopez | J39: Ignacio Gonzalez | K39: nariv@misericordiadevoto.edu.ar | L39: CABA | M39: Devoto | N39: 30 | O39: 6º Secundaria (Prov.) / 5º Media (CABA) | P39: 3 | Q39: 2 | R39: 5 | T39: No | U39: Si | V39: Jornada simple: sólo turno tarde (12.30 a 16:00 hs.) | W39: Miércoles 26/4 | AV39: No | AW39: No | AX39: Si | AY39: No | AZ39: No | BA39: No | BB39: Si | BC39: No | BD39: Si | BE39: No | BF39: No | BG39: No | BH39: No | BI39: Si | BJ39: No | BK39: No | BL39: No | BM39: No | BN39: No | BO39: No | BP39: No | BR39: No
A40: 45003.553 | B40: nariv@misericordiadevoto.edu.ar | C40: Colegio Nuestra Señora de la Misericordia de devoto A-110 | D40: 020086000 | E40: 9. Liceos / Normales / Colegios / Institutos orientados en ciencias sociales y/o humanidades | F40: Humanidades y Cs. Sociales | G40: Privada | H40: Maria Adriana Lopez | I40: Victoria Anahí Nari | J40: Ignacio Gonzalez | K40: nariv@misericordiadevoto.edu.ar | L40: CABA | M40: Devoto | N40: 28 | O40: 6º Secundaria (Prov.) / 5º Media (CABA) | P40: 3 | Q40: 2 | R40: 5 | T40: No | U40: Si | V40: Jornada simple: sólo turno tarde (12.30 a 16:00 hs.) | W40: Miércoles 26/4 | AV40: No | AW40: No | AX40: Si | AY40: No | AZ40: No | BA40: No | BB40: Si | BC40: No | BD40: Si | BE40: No | BF40: No | BG40: No | BH40: No | BI40: Si | BJ40: No | BK40: No | BL40: No | BM40: No | BN40: No | BO40: No | BP40: No | BQ40: No | BR40: No
...

Sheet Hoja 6
A1: 10 | B1: Liceos / Normales / Colegios / Institutos de otras orientaciones | C1: 10. Liceos / Normales / Colegios / Institutos de otras orientaciones
A2: 5 | B2: Técnicas área producción (electromecánica, mecánica, metalurgia, electricidad, automotores, refrigeración, construcciones, maestro mayor de obras, aeronáutica, naval, aviónico, óptico, en geografía matemática) | C2: 5. Técnicas área producción (electromecánica, mecánica, metalurgia, electricidad, automotores, refrigeración, construcciones, maestro mayor de obras, aeronáutica, naval, aviónico, óptico, en geografía matemática)
A3: 1 | B3: Liceos / Normales / Colegios / Institutos orientados en ciencias naturales y/o exactas | C3: 1. Liceos / Normales / Colegios / Institutos orientados en ciencias naturales y/o exactas
A4: 2 | B4: Técnicas en computación, electrónica, informática | C4: 2. Técnicas en computación, electrónica, informática
A5: 9 | B5: Liceos / Normales / Colegios / Institutos orientados en ciencias sociales y/o humanidades | C5: 9. Liceos / Normales / Colegios / Institutos orientados en ciencias sociales y/o humanidades
A6: 3 | B6: Técnicas en administración de empresas, administración de las organizaciones, servicios turísticos, multimedios | C6: 3. Técnicas en administración de empresas, administración de las organizaciones, servicios turísticos, multimedios
A7: 4 | B7: Artísticas de todas las orientaciones | C7: 4. Artísticas de todas las orientaciones
A8: 13 | B8: Formación permanente de jóvenes y adultos | C8: 13. Formación permanente de jóvenes y adultos
A9: 11 | B9: Rurales de todas las orientaciones | C9: 11. Rurales de todas las orientaciones

Sheet Corrida de prioridades
A1: Marca temporal | B1: Dirección de correo electrónico | C1: Nombre OFICIAL y COMPLETO de la institución educativa | D1: Código Único de Escuela (CUE) | E1: Tipo de escuela y orientación | F1: Especifique su orientación | G1: Gestión | H1: Nombre y apellido del/la docente responsable de la visita | I1: Nombre y apellido del/la docente acompañante 1 | J1: Nombre y apellido del/la docente acompañante 2 | K1: Dirección de correo electrónico para recibir resultado de la asignación | L1: Ubicación general de la escuela | M1: Barrio/Localidad de la escuela | N1: Cantidad de alumnos que asistirán | O1: Curso que asistirá | P1: Conectividad en la institución | Q1: Acceso a las ciencias exactas y naturales | R1: Porcentaje aproximado de estudiantes de familias de bajos recursos | S1: Exprese observaciones o comentarios que considere pertinentes | T1: Turno/s solicitado/s [Turno mañana (9:00 a 12.30 hs.)] | U1: Turno/s solicitado/s [Turno tarde (12.30 a 16:00 hs.)] | V1: Fecha solicitada | W1: CHARLAS [9:30 Redes sociales: la matemática detrás de los "influencers". Rocío Balderrama] | X1: CHARLAS [11:30 La Biblio junto a... la calculadora. Historias que no hacen historia. Juan Carlos Pedraza] | Y1: CHARLAS [14:00 ¿Cómo hacer ciencia con Twitter? Sofía del Pozo] | Z1: ESTACIONES INTERACTIVAS [9:30] | AA1: ESTACIONES INTERACTIVAS [10:30] | AB1: ESTACIONES INTERACTIVAS [11:30] | AC1: ESTACIONES INTERACTIVAS [13:00] | AD1: ESTACIONES INTERACTIVAS [14:00] | AE1: ESTACIONES INTERACTIVAS [15:00] | AF1: TALLERES [9:30] | AG1: TALLERES [10:30] | AH1: TALLERES [11:30] | AI1: TALLERES [14:00] | AJ1: TALLERES [15:00] | AK1: ARTE MATEMÁTICO [9:30] | AL1: ARTE MATEMÁTICO [10:30] | AM1: ARTE MATEMÁTICO [11:30] | AN1: ARTE MATEMÁTICO [14:00] | AO1: ARTE MATEMÁTICO [15:00] | AP1: VISITAS GUIADAS TEMÁTICAS [10:30] | AQ1: VISITAS GUIADAS TEMÁTICAS [11:30] | AR1: VISITAS GUIADAS TEMÁTICAS [14:00] | AS1: VISITAS GUIADAS TEMÁTICAS [15:00] | AT1: Exprese cualquier aclaración sobre la solicitud de inscripción que facilite la administración de vacantes. | AU1: CHARLAS [9:30 Desorden ordenado, ¡qué caos es esto! Paula Kuna] | AV1: CHARLAS [11:30 ¿Tenés una idea para cambiar el mundo? Primero simulalo. Rodrigo Castro] | AW1: CHARLAS [14:00 Embaldosados Fractales. Ursula Molter] | AX1: ESTACIONES INTERACTIVAS [9:30] | AY1: ESTACIONES INTERACTIVAS [10:30] | AZ1: ESTACIONES INTERACTIVAS [11:30] | BA1: ESTACIONES INTERACTIVAS [13:00] | BB1: ESTACIONES INTERACTIVAS [14:00] | BC1: ESTACIONES INTERACTIVAS [15:00] | BD1: TALLERES [9.30] | BE1: TALLERES [10:30] | BF1: TALLERES [11:30] | BG1: TALLERES [14:00] | BH1: TALLERES [15:00] | BI1: ARTE MATEMÁTICO [9:30] | BJ1: ARTE MATEMÁTICO [10:30] | BK1: ARTE MATEMÁTICO [11:30] | BL1: ARTE MATEMÁTICO [14:00] | BM1: ARTE MATEMÁTICO [15:00] | BN1: VISITA GUIADA [10:30] | BO1: VISITA GUIADA [11:30] | BP1: VISITA GUIADA [14:00] | BQ1: VISITA GUIADA [15:00] | BR1: Exprese cualquier aclaración sobre la solicitud de inscripción que facilite la administración de vacantes. | BS1: CHARLAS [9:30 Geometría proyectiva, fotografía y la final del mundo. Charly Di Fiore] | BT1: CHARLAS [11:30 Detective de datos. Guillermo Solovey] | BU1: CHARLAS [14:00 Datos y deportes. Iván Monardo] | BV1: ESTACIONES INTERACTIVAS [9:30] | BW1: ESTACIONES INTERACTIVAS [10:30] | BX1: ESTACIONES INTERACTIVAS [11:30] | BY1: ESTACIONES INTERACTIVAS [13:00] | BZ1: ESTACIONES INTERACTIVAS [14:00] | CA1: ESTACIONES INTERACTIVAS [15:00] | CB1: TALLERES [9:30] | CC1: TALLERES [10:30 ] | CD1: TALLERES [11:30] | CE1: TALLERES [14:00] | CF1: TALLERES [15:00] | CG1: ARTE MATEMÁTICO [9:30] | CH1: ARTE MATEMÁTICO [10:30] | CI1: ARTE MATEMÁTICO [11:30] | CJ1: ARTE MATEMÁTICO [14:00] | CK1: ARTE MATEMÁTICO [15:00] | CL1: VISITA GUIADA [10:30] | CM1: VISITA GUIADA [11:30] | CN1: VISITA GUIADA [14:00] | CO1: VISITA GUIADA [15:00] | CP1: Exprese cualquier aclaración sobre la solicitud de inscripción que facilite la administración de vacantes.
A2: 45003.815 | B2: malarcon1012@gmail.com | C2: Escuela de Educación Secundaria Técnica Nª1 | D2: 061213800 | E2: 5. Técnicas área producción (electromecánica, mecánica, metalurgia, electricidad, automotores, refrigeración, construcciones, maestro mayor de obras, aeronáutica, naval, aviónico, óptico, en geografía matemática) | F2: en construcción .los alumnos egresan con el titulo Maestro Mayor de Obra | G2: Estatal | H2: Mirna Alarcón | I2: Sandra Casan | J2: Roberto Tignianelli | K2: malarcon1012@gmail.com | L2: INTERIOR DE LA PROVINCIA DE BUENOS AIRES | M2: San Isidro | N2: 34 | O2: 7º Técnica (Prov.) / 6º Técnica (CABA) | P2: 3 | Q2: 3 | R2: 88 | S2: La mayoría de los alumnos son de barrios carenciados | T2: No | U2: Si | V2: Martes 25/4 | W2: No | X2: No | Y2: Si | Z2: No | AA2: No | AB2: Si | AC2: Si | AD2: No | AE2: No | AJ2: Si | AO2: Si | AP2: Si | AT2: Estaremos muy satisfecho, en las aérea o talleres que uds nos designen
A3: 45000.682 | B3: reboiras.juan@colegioesclavas.edu.ar | C3: Instituto Esclavas del Sagrado Corazón de Jesús (A-14) | D3: 020094900 | E3: 1. Liceos / Normales / Colegios / Institutos orientados en ciencias naturales y/o exactas | F3: Ciencias Naturales | G3: Privada | H3: Juan Martín Reboiras | I3: Patricia Julia Castro | K3: reboiras.juan@colegioesclavas.edu.ar | L3: CABA | M3: Belgrano | N3: 30 | O3: 6º Secundaria (Prov.) / 5º Media (CABA) | P3: 2 | Q3: 3 | R3: 0 | T3: Si | U3: Si | V3: Jueves 27/4 | BS3: Si | BT3: Si | BU3: Si | BV3: Si | BW3: Si | BX3: Si | BY3: Si | BZ3: Si | CA3: Si | CB3: Si | CC3: Si | CD3: Si | CE3: Si | CF3: Si | CG3: Si | CH3: Si | CI3: Si | CJ3: Si | CK3: Si | CL3: Si | CM3: Si | CN3: Si | CO3: Si
A4: 45005.59 | B4: auniversidad@goethe.edu.ar | C4: INSTITUTO ESCOLAR GOETHE | D4: 061215200 | E4: 1. Liceos / Normales / Colegios / Institutos orientados en ciencias naturales y/o exactas | F4: Ciencias Naturales | G4: Privada | H4: Tatiana Wolff | I4: Melina Seifert | J4: Matthias FaBit | K4: auniversidad@goethe.edu.ar | L4: ÁREA METROPOLITANA DE BUENOS AIRES | M4: San Isidro | N4: 35 | O4: 6º Secundaria (Prov.) / 5º Media (CABA) | P4: 5 | Q4: 5 | R4: 0 | T4: Si | U4: Si | V4: Martes 25/4 | W4: Si | X4: No | Y4: Si | Z4: No | AA4: No | AB4: No | AC4: No | AD4: No | AE4: Si | AF4: No | AG4: Si | AH4: No | AI4: No | AJ4: No | AK4: No | AL4: No | AM4: No | AN4: No | AO4: No | AP4: No | AQ4: Si | AR4: No | AS4: No
A5: 45001.578 | B5: gabriela.gonzalog@gmail.com | C5: Colegio irlandes | D5: 061602200 | E5: 1. Liceos / Normales / Colegios / Institutos orientados en ciencias naturales y/o exactas | F5: Ciencias sociales | G5: Privada | H5: Maria Gabriela Gonzalo Grilo | I5: Sabrina alvarenga | J5: Romina ramos | K5: gabriela.gonzalog@gmail.com | L5: ÁREA METROPOLITANA DE BUENOS AIRES | M5: Almirante brown | N5: 28 | O5: 6º Secundaria (Prov.) / 5º Media (CABA) | P5: 5 | Q5: 3 | R5: 0 | T5: Si | U5: No | V5: Miércoles 26/4 | AU5: Si | AV5: No | AW5: No | AX5: No | AY5: No | AZ5: Si | BA5: No | BB5: No | BC5: No | BD5: No | BE5: No | BF5: No | BG5: No | BH5: No | BI5: No | BJ5: Si | BK5: No | BL5: No | BM5: No | BN5: No | BO5: No | BP5: No | BQ5: No
A6: 45001.629 | B6: laura_p_lencina@yahoo.com.ar | C6: Instituto santa ana | D6: 061123600 | E6: 1. Liceos / Normales / Colegios / Institutos orientados en ciencias naturales y/o exactas | F6: Cs Nat | G6: Privada | H6: Laura Lencina | I6: Cecilia Gagliano | K6: laura_p_lencina@yahoo.com.ar | L6: ÁREA METROPOLITANA DE BUENOS AIRES | M6: Villa Ballester | N6: 35 | O6: 6º Secundaria (Prov.) / 5º Media (CABA) | P6: 5 | Q6: 4 | R6: 2 | T6: Si | U6: No | V6: Martes 25/4 | W6: Si | X6: No | Y6: No | Z6: No | AA6: Si | AB6: No | AC6: No | AD6: No | AE6: No | AG6: Si | AH6: Si | AM6: Si
A7: 45001.625 | B7: laura_p_lencina@yahoo.com.ar | C7: Instituto Santa Ana | D7: 061123600 | E7: 1. Liceos / Normales / Colegios / Institutos orientados en ciencias naturales y/o exactas | F7: Cs sociales | G7: Privada | H7: Lencina Laura | I7: Gagliano Cecilia | K7: laura_p_lencina@yahoo.com.ar | L7: ÁREA METROPOLITANA DE BUENOS AIRES | M7: Villa Ballester | N7: 35 | O7: 6º Secundaria (Prov.) / 5º Media (CABA) | P7: 5 | Q7: 4 | R7: 2 | T7: Si | U7: No | V7: Martes 25/4 | W7: Si | X7: No | Y7: No | Z7: No | AA7: Si | AB7: No | AC7: No | AD7: No | AE7: No | AG7: Si | AH7: Si | AM7: Si | AP7: Si | AQ7: Si | AR7: No | AS7: No
A8: 45001.66 | B8: laura_p_lencina@yahoo.com.ar | C8: Instituto santa ana | D8: 061123600 | E8: 1. Liceos / Normales / Colegios / Institutos orientados en ciencias naturales y/o exactas | F8: Economía | G8: Privada | H8: Lencina Laura | I8: Gagliano Cecilia | J8: Cintia Merchan | K8: laura_p_lencina@yahoo.com.ar | L8: ÁREA METROPOLITANA DE BUENOS AIRES | M8: Villa Ballester | N8: 35 | O8: 6º Secundaria (Prov.) / 5º Media (CABA) | P8: 5 | Q8: 4 | R8: 2 | T8: Si | U8: No | V8: Martes 25/4 | W8: Si | X8: No | Y8: No | Z8: No | AA8: Si | AB8: Si | AC8: No | AD8: No | AE8: No | AG8: Si | AL8: Si | AM8: Si
A9: 45005.919 | B9: vicedireccionsagradocorazon@gmail.com | C9: Colegio Sagrado Corazon de jesus | D9: 061607500 | E9: 1. Liceos / Normales / Colegios / Institutos orientados en ciencias naturales y/o exactas | F9: Economía y Administración | G9: Privada | H9: Claudio Bedoya | I9: Gabriela Lujan | J9: Ileana Benedetti | K9: vicedireccionsagradocorazon@gmail.com | L9: CABA | M9: Quilmes | N9: 29 | O9: 6º Secundaria (Prov.) / 5º Media (CABA) | P9: 4 | Q9: 4 | R9: 5 | T9: Si | U9: No | V9: Miércoles 26/4 | AU9: Si | AV9: Si | AW9: No | AX9: No | AY9: Si | AZ9: No | BA9: No | BB9: No | BC9: No | BD9: No | BE9: No | BF9: No | BG9: Si | BH9: No | BI9: No | BJ9: No | BK9: No | BL9: No | BM9: Si | BN9: Si | BO9: No | BP9: No | BQ9: No | BR9: De ser necesario, para poder aprovechar todas las actividades, podemos quedarnos en el turno tarde también.
A10: 45000.828 | B10: d.ana.gomez@sanrafael.esc.edu.ar | C10: Instituto San Rafael (A-120) | D10: 020133700 | E10: 1. Liceos / Normales / Colegios / Institutos orientados en ciencias naturales y/o exactas | F10: Administración | G10: Privada | H10: Ana Paula Gómez Tascón | I10: Gabriel Giberti | K10: d.ana.gomez@sanrafael.esc.edu.ar | L10: CABA | M10: Villa Devoto | N10: 30 | O10: 6º Secundaria (Prov.) / 5º Media (CABA) | P10: 3 | Q10: 1 | R10: 10 | T10: Si | U10: No | V10: Miércoles 26/4 | AU10: No | AV10: Si | AW10: No | AX10: No | AY10: No | AZ10: No | BA10: No | BB10: No | BC10: No | BD10: Si | BI10: No | BJ10: No | BK10: No | BL10: No | BM10: No | BN10: Si | BO10: No | BP10: No | BQ10: No | BR10: Me encantaría q los estudiantes de 5to año vean algo de fractales pero si cada posta es de una hora, no nos darán los tiempos. Muchas gracias
A11: 45005.811 | B11: cami_zabala@yahoo.com.ar | C11: Instituto Madre Maria Luisa Clarac | D11: 060703300 | E11: 1. Liceos / Normales / Colegios / Institutos orientados en ciencias naturales y/o exactas | F11: Ciencias Naturales | G11: Privada | H11: Camila Zabala Lindermann | I11: Fernandez Mariela | J11: Gutierrez Karina | K11: cami_zabala@yahoo.com.ar | L11: ÁREA METROPOLITANA DE BUENOS AIRES | M11: Gregorio de Laferrere | N11: 38 | O11: 6º Secundaria (Prov.) / 5º Media (CABA) | P11: 3 | Q11: 4 | R11: 10 | T11: Si | U11: Si | V11: Martes 25/4 | W11: Si | X11: Si | Y11: Si | Z11: Si | AA11: Si | AB11: Si | AC11: Si | AD11: No | AE11: No | AF11: Si | AG11: Si | AH11: Si | AI11: No | AJ11: No | AK11: Si | AL11: Si | AM11: Si | AN11: No | AO11: No | AP11: Si | AQ11: Si | AR11: Si | AS11: No
A12: 45006.488 | B12: mpflosi@gmail.com | C12: Escuela del Sol | D12: 061296100 | E12: 1. Liceos / Normales / Colegios / Institutos orientados en ciencias naturales y/o exactas | F12: Ciencias naturales | G12: Privada | H12: Flosi Maria Paola | I12: Liliana Zacarías | J12: Ayelen Ferreyra | K12: mpflosi@gmail.com | L12: ÁREA METROPOLITANA DE BUENOS AIRES | M12: Berazategui | N12: 34 | O12: 6º Secundaria (Prov.) / 5º Media (CABA) | P12: 3 | Q12: 3 | R12: 10 | T12: Si | U12: No | V12: Martes 25/4 | W12: Si | X12: No | Y12: No | Z12: No | AA12: No | AB12: Si | AC12: No | AD12: No | AE12: No | AF12: No | AG12: No | AH12: No | AI12: Si | AJ12: No | AK12: No | AL12: No | AM12: Si | AN12: No | AO12: No | AP12: Si
A13: 45001.938 | B13: gonzalez.mercedes.sango@gmail.com | C13: Instituto San José | D13: 020169900 | E13: 1. Liceos / Normales / Colegios / Institutos orientados en ciencias naturales y/o exactas | F13: Gestión | G13: Privada | H13: Mercedes GONZALEZ | I13: Carolina Malter | J13: Diego Pozzi | K13: gonzalez.mercedes.sanjo@gmail.com | L13: CABA | M13: Balvanera | N13: 25 | O13: 6º Secundaria (Prov.) / 5º Media (CABA) | P13: 5 | Q13: 5 | R13: 10 | T13: Si | U13: Si | V13: Jueves 27/4 | BS13: No | BT13: No | BU13: No | BV13: No | BW13: No | BX13: Si | BY13: Si | BZ13: Si | CA13: Si | CB13: No | CC13: No | CD13: No | CE13: No | CF13: No | CG13: Si | CH13: Si | CI13: Si | CJ13: Si | CK13: Si | CL13: Si | CM13: Si | CN13: Si | CO13: Si | CP13: Según el horario que ustedes nos otorguen deseamos realizar una visita guiada, participar de las estaciones interactivas y del Arte Matemático.
A14: 45001.944 | B14: gonzalez.mercedes.sanjo@gmail.com | C14: Instituto San José | D14: 020169900 | E14: 1. Liceos / Normales / Colegios / Institutos orientados en ciencias naturales y/o exactas | F14: Gestión y economía | G14: Privada | H14: Mercedes Gonzalez | I14: Carolina Malter | J14: Diego Pozzi | K14: gonzalez.mercedes.sanjo@gmail.com | L14: CABA | M14: Balvanera | N14: 30 | O14: 6º Secundaria (Prov.) / 5º Media (CABA) | P14: 5 | Q14: 5 | R14: 10 | T14: Si | U14: Si | V14: Jueves 27/4 | BS14: No | BT14: No | BU14: No | BV14: Si | BW14: Si | BX14: Si | BY14: Si | BZ14: Si | CA14: Si | CB14: No | CC14: No | CD14: No | CE14: No | CF14: No | CG14: Si | CH14: Si | CI14: Si | CJ14: Si | CK14: Si | CL14: Si | CM14: Si | CN14: Si | CO14: Si | CP14: Según los horarios que ustedes dispongan deseamos participar de VISITA GUIADA, ESTACIONES INTERACTIVAS y ARTE MATEMÁTICO.
A15: 45002.413 | B15: yaninasdiaz86@gmail.com | C15: ENS N°2 "Mariano Acosta" | D15: 020086600 | E15: 1. Liceos / Normales / Colegios / Institutos orientados en ciencias naturales y/o exactas | F15: Normal | G15: Estatal | H15: Diaz Yanina | I15: Redin Clarisa | J15: Grandal Natalia | K15: yaninas.diaz@bue.edu.ar | L15: CABA | M15: Balvanera | N15: 35 | O15: 6º Secundaria (Prov.) / 5º Media (CABA) | P15: 4 | Q15: 4 | R15: 10 | T15: Si | U15: Si | V15: Martes 25/4 | W15: Si | X15: No | Y15: No | Z15: No | AA15: No | AB15: Si | AC15: Si | AD15: No | AE15: No | AF15: No | AG15: Si | AH15: Si | AI15: No | AJ15: No | AK15: No | AL15: Si | AM15: Si | AN15: No | AO15: No | AP15: Si | AQ15: Si | AR15: No | AS15: No
A16: 45002.44 | B16: gabrielanet@liceobrown.edu.ar | C16: LICEO NAVAL MILITAR ALMIRANTE GUILLERMO BROWN | D16: 069003200 | E16: 1. Liceos / Normales / Colegios / Institutos orientados en ciencias naturales y/o exactas | F16: Ciencias Naturales | G16: Estatal | H16: Gabriela Patricia Net | I16: Ariel Brandani | J16: Cynthia Castro | K16: gabrielanet@liceobrown.edu.ar | L16: ÁREA METROPOLITANA DE BUENOS AIRES | M16: Vicente López | N16: 23 | O16: 6º Secundaria (Prov.) / 5º Media (CABA) | P16: 4 | Q16: 3 | R16: 15 | T16: Si | U16: No | V16: Jueves 27/4 | BS16: Si | BT16: Si | BU16: No | BV16: Si | BW16: Si | BX16: No | BY16: No | BZ16: No | CA16: No | CB16: Si | CC16: Si | CD16: No | CE16: No | CF16: No | CG16: Si | CH16: Si | CI16: No | CJ16: No | CK16: No | CL16: Si | CM16: No | CN16: No | CO16: No
A17: 45004.53 | B17: mapaulasuarez@yahoo.com.ar | C17: INSTITUTO SOCIAL MILITAR DOCTOR DAMASO CENTENO | D17: 029003000 | E17: 1. Liceos / Normales / Colegios / Institutos orientados en ciencias naturales y/o exactas | F17: CIENCIAS NATURALES | G17: Estatal | H17: MARIA PAULA SUAREZ | I17: ADRIANA HOZ | J17: BRUNO BAGNIOLE | K17: mapaulasuarez@yahoo.com.ar | L17: CABA | M17: CABALLITO | N17: 40 | O17: 6º Secundaria (Prov.) / 5º Media (CABA) | P17: 5 | Q17: 5 | R17: 20 | T17: Si | U17: No | V17: Martes 25/4 | W17: Si | X17: Si | Y17: No | Z17: Si | AA17: Si | AB17: Si | AC17: No | AD17: No | AE17: No | AF17: Si | AG17: Si | AH17: Si | AI17: No | AJ17: No | AK17: Si | AL17: Si | AM17: Si | AN17: No | AO17: No | AP17: Si | AQ17: Si | AR17: No | AS17: No | AT17: COMO TODOS LOS AÑOS, ESPERAMOS PODER VISITARLOS CON ESTE NUEVO GRUPO DE ALUMNOS
A18: 45004.534 | B18: mapaulasuarez@yahoo.com.ar | C18: INSTITUTO SOCIAL MILITAR DOCTOR DAMASO CENTENO | D18: 029003000 | E18: 1. Liceos / Normales / Colegios / Institutos orientados en ciencias naturales y/o exactas | F18: CIENCIAS NATURALES | G18: Estatal | H18: LISETTE MENDEZ | I18: FLORENCIA LOPEZ DE VOLVER | J18: ALVARO CORTES CONTI | K18: mapaulasuarez@yahoo.com.ar | L18: CABA | M18: CABALLITO | N18: 40 | O18: 6º Secundaria (Prov.) / 5º Media (CABA) | P18: 5 | Q18: 5 | R18: 20 | T18: Si | U18: No | V18: Miércoles 26/4 | AU18: Si | AV18: Si | AW18: No | AX18: Si | AY18: Si | AZ18: Si | BA18: No | BB18: No | BC18: No | BD18: Si | BE18: Si | BF18: Si | BG18: No | BH18: No | BI18: Si | BJ18: Si | BK18: Si | BL18: No | BM18: No | BN18: Si | BO18: Si | BP18: No | BQ18: No
A19: 45004.538 | B19: mapaulasuarez@yahoo.com.ar | C19: INSTITUTO SOCIAL MILITAR DOCTOR DAMASO CENTENO | D19: 029003000 | E19: 1. Liceos / Normales / Colegios / Institutos orientados en ciencias naturales y/o exactas | F19: CIENCIAS NATURALES | G19: Estatal | H19: FLAVIA TERRIZZANO | I19: ANTONIO VUISSO | J19: ESTEFANIA DENIS | K19: mapaulasuarez@yahoo.com.ar | L19: CABA | M19: CABALLITO | N19: 35 | O19: 6º Secundaria (Prov.) / 5º Media (CABA) | P19: 5 | Q19: 5 | R19: 20 | T19: Si | U19: No | V19: Jueves 27/4 | BS19: Si | BT19: Si | BU19: No | BV19: Si | BW19: Si | BX19: Si | BY19: No | BZ19: No | CA19: No | CB19: Si | CC19: Si | CD19: Si | CE19: No | CF19: No | CG19: Si | CH19: Si | CI19: Si | CJ19: No | CK19: No | CL19: Si | CM19: Si | CN19: No | CO19: No
A20: 45000.748 | B20: patferre@gmail.com | C20: Colegio de la Reconquista | D20: 061629100 | E20: 1. Liceos / Normales / Colegios / Institutos orientados en ciencias naturales y/o exactas | F20: Cs Naturales | G20: Privada | H20: Patricia Ferreyra | I20: Karina Barrientos | J20: Liliana Descalzo | K20: patferre@gmail.com | L20: ÁREA METROPOLITANA DE BUENOS AIRES | M20: Tigre/Tigre | N20: 30 | O20: 6º Secundaria (Prov.) / 5º Media (CABA) | P20: 5 | Q20: 1 | R20: 20 | T20: Si | U20: No | V20: Martes 25/4 | W20: Si | X20: No | Y20: Si | Z20: No | AA20: Si | AB20: Si | AC20: Si | AD20: No | AE20: No | AF20: No | AG20: No | AH20: Si | AI20: No | AJ20: No | AK20: No | AL20: Si | AM20: Si | AN20: Si | AO20: No
A21: 45001.648 | B21: valeriatardioli@gmail.com | C21: Instituto Proyección XXI | D21: 060455500 | E21: 1. Liceos / Normales / Colegios / Institutos orientados en ciencias naturales y/o exactas | F21: Sociales | G21: Privada | H21: Paola Flossi | I21: Estrella Lopez | J21: Valeria Tardioli | K21: valeriatardioli@gmail.com | L21: ÁREA METROPOLITANA DE BUENOS AIRES | M21: Bernal oeste | N21: 31 | O21: 6º Secundaria (Prov.) / 5º Media (CABA) | P21: 4 | Q21: 1 | R21: 25 | T21: Si | U21: Si | V21: Jueves 27/4 | BS21: No | BT21: No | BU21: Si | BV21: Si | BW21: No | BX21: No | BY21: No | BZ21: No | CA21: No | CB21: No | CC21: No | CD21: Si | CE21: No | CF21: No | CG21: No | CH21: Si | CI21: No | CJ21: No | CK21: No | CL21: Si | CM21: No | CN21: No | CO21: No
A22: 45001.649 | B22: valeriatardioli@gmail.com | C22: Instituto Proyección XXI | D22: 060455500 | E22: 1. Liceos / Normales / Colegios / Institutos orientados en ciencias naturales y/o exactas | F22: Sociales | G22: Privada | H22: Paola Flossi | I22: Estrella Lopez | J22: Valeria Tardioli | K22: valeriatardioli@gmail.com | L22: ÁREA METROPOLITANA DE BUENOS AIRES | M22: Bernal Oeste | N22: 25 | O22: 6º Secundaria (Prov.) / 5º Media (CABA) | P22: 4 | Q22: 1 | R22: 25 | T22: Si | U22: Si | V22: Jueves 27/4 | BS22: No | BT22: No | BU22: Si | BV22: Si | BW22: No | BX22: No | BY22: No | BZ22: No | CA22: No | CB22: No | CC22: No | CD22: Si | CE22: No | CF22: No | CG22: No | CH22: Si | CI22: No | CJ22: No | CK22: No | CL22: Si | CM22: No | CN22: No | CO22: No
A23: 45001.395 | B23: betsabescerba@gmail.com | C23: EES N°15 | D23: 061805000 | E23: 1. Liceos / Normales / Colegios / Institutos orientados en ciencias naturales y/o exactas | F23: Ciencias naturales | G23: Estatal | H23: Aldana Scerba | I23: Griselda Mendez | J23: Romina Grillo | K23: betsabescerba@gmail.com | L23: ÁREA METROPOLITANA DE BUENOS AIRES | M23: Hurlingham | N23: 11 | O23: 6º Secundaria (Prov.) / 5º Media (CABA) | P23: 2 | Q23: 1 | R23: 30 | T23: Si | U23: No | V23: Jueves 27/4 | BS23: Si | BT23: No | BU23: No | BV23: No | BW23: Si | BX23: No | BY23: No | BZ23: No | CA23: No | CB23: No | CC23: No | CD23: No | CE23: No | CF23: No | CG23: No | CH23: No | CI23: Si | CJ23: No | CK23: No | CL23: No | CM23: No | CN23: No | CO23: No
